Workbook

Sheet 1. Cover
B2: [UNIVERSITY NAME]
B3: Internal Quality Assurance Cell (IQAC)
B5: NAAC Binary Accreditation Framework | Attribute 4 – Financial Resources & Management (50)
B6: Metric 4.3 – Sustainability: Strategies for Financial Sustainability (Weightage: 10)
B7: (a) Creation of Corpus • (b) Diversification of Investments
B8: Data Capture, Compliance & Evidence Workbook • Financial Years 2025-26, 2024-25, 2023-24 and 2022-23 • All amounts in INR Lakhs
B10: ABSTRACT
B11: This workbook is the institutional tool for preparing NAAC Metric 4.3 – Sustainability. Unlike Metrics 4.1 and 4.2, which are ratio-based, Metric 4.3 is an options-based metric: the institution must demonstrate, through audited accounts, the strategies it follows for long-term financial sustainability – (a) Creation of Corpus and (b) Diversification of Investments. The workbook records, for four financial years (2025-26, 2024-25, 2023-24 and 2022-23): the year-wise movement of the Corpus / Endowment Fund (opening balance, additions, withdrawals and closing balance); the investment portfolio as at 31 March of each year, by type of instrument; investment income; and the policies and strategies adopted with their approvals. It then automatically evaluates compliance with options (a) and (b), computes supporting indicators – corpus growth, months of operating expenditure covered by corpus, number of investment categories, concentration and a diversification index – and pre-fills a Chartered Accountant (CA) certificate. Guidelines, a worked example and an evidence checklist are included.
B13: INTRODUCTION
B14: Why this metric matters: A university is financially sustainable when it can continue to deliver quality education over the long term, even if income falls temporarily or unforeseen expenses arise. NAAC looks for two concrete strategies: (a) Creation of Corpus – a permanent or long-term fund built from surpluses, sponsoring-body contributions, endowments and donations, whose principal is preserved and whose income supports the institution. A corpus provides a financial cushion, satisfies statutory endowment requirements applicable to private universities, and signals prudent financial management. (b) Diversification of Investments – placing surplus and corpus funds across different, safe and permitted instruments (fixed deposits in several scheduled banks, government securities, PSU bonds, debt mutual funds etc.) instead of concentrating them in one instrument or one bank. Diversification reduces risk, improves returns and ensures liquidity. How it is assessed: The institution selects the options it fulfils and supports them with audited income and expenditure statements and balance sheets, highlighting the specific components, certified by a CA. Link with other metrics: The corpus is normally built from the operating surplus shown in Metric 4.2 and from capital contributions shown in Metric 4.1. Investment income appears as revenue income in Metric 4.2. Financial controls over investments are covered in Metric 4.4.
B16: OBJECTIVES OF THIS WORKBOOK
B17: 1. Record corpus movement and investment holdings in a standard, year-wise format traceable to the audited Balance Sheet. 2. Automatically test whether options (a) Creation of Corpus and (b) Diversification of Investments are fulfilled for each year. 3. Compute indicators that demonstrate the strength of the strategy – corpus growth, months of cover, diversification index and investment yield. 4. Document the policies, approvals and strategies adopted by the University. 5. Track every supporting document and generate the CA certificate.
B19: WORKBOOK STRUCTURE
B20: Sheet | C20: Purpose | D20: Who fills / uses | E20: Action required
B21: 1. Cover | C21: Abstract, introduction, objectives and structure | D21: All users | E21: Read first
B22: 2. Guidelines | C22: Definitions, compliance criteria, procedure, include/exclude rules, indicators, documents, common errors | D22: Finance Office & IQAC | E22: Read before entering data
B23: 3. Corpus Fund | C23: Year-wise movement of Corpus / Endowment Fund | D23: Finance Office | E23: Enter figures in cream cells
B24: 4. Investment Portfolio | C24: Investments by instrument as at 31 March, number of banks, investment income | D24: Finance Office | E24: Enter figures in cream cells
B25: 5. Strategies & Policies | C25: Sustainability strategies, approving body, date and evidence | D25: Finance Officer & IQAC | E25: Describe and select status
B26: 6. Summary & Compliance | C26: Option (a) and (b) compliance, indicators, interpretation and chart | D26: IQAC (auto-calculated) | E26: Review only – no entry
B27: 7. Worked Example | C27: Illustration with hypothetical figures | D27: Training / reference | E27: Read only
B28: 8. Document Checklist | C28: Status of every supporting document, FY-wise | D28: IQAC & Finance Office | E28: Select status from drop-down
B29: 9. CA Certificate | C29: Certificate format pre-filled from the Summary | D29: CA / Finance Officer | E29: Print, verify and sign
B31: CELL COLOUR LEGEND
B32: Cream fill, blue text | C32: Input cell – enter data here (INR Lakhs, two decimals)
B33: Light navy fill, black text | C33: Formula / subtotal – do not overwrite
B34: Green text | C34: Value linked from another sheet – do not overwrite
B35: Navy fill, gold/white text | C35: Headings and sections
B37: Prepared by: IQAC, [University Name] | Version 1.0 | Basis: NAAC Binary Accreditation Framework – Metrics for Manual (Base), Draft Version
B38: Note: The NAAC draft lists the two options but does not publish the scoring method. Compliance tests and indicator bands in this workbook are indicative IQAC guidance; update them when NAAC notifies the final SOP.

Sheet 2. Guidelines
B2: GUIDELINES FOR PREPARING METRIC 4.3
B3: G1. WHAT NAAC ASKS
B4: Option | C4: Strategy | D4: What it means | E4: Evidence NAAC asks for
B5: a | C5: Creation of Corpus | D5: A dedicated Corpus / Endowment / Reserve Fund exists in the Balance Sheet, has been created or strengthened during the assessment period, and its principal is preserved | E5: Audited Balance Sheet and I&E statement highlighting the Corpus Fund schedule, certified by CA; audit extracts certified by CA
B6: b | C6: Diversification of Investments | D6: Corpus and surplus funds are invested across more than one type of permitted instrument and/or more than one institution, as per an approved investment policy | E6: Audited Balance Sheet investment schedule highlighting the instruments, certified by CA; audit extracts certified by CA
B8: G2. ASSESSMENT PERIOD AND YEAR BASIS
B9: • Use FINANCIAL YEARS (1 April – 31 March). • NAAC assessment period = FY 2025-26, FY 2024-25 and FY 2023-24. FY 2022-23 is captured as a baseline for growth calculations; its closing balance becomes the opening balance of FY 2023-24. • Balances (corpus, investments) are taken AS AT 31 MARCH of each FY; movements (additions, withdrawals, income) are FOR THE YEAR. • All amounts in INR Lakhs, two decimals.
B11: G3. COMPLIANCE CRITERIA USED IN THIS WORKBOOK (INDICATIVE)
B12: Option | C12: Test applied | D12: Result shown | E12: Notes
B13: a | C13: Closing corpus at 31 March of the latest FY is greater than zero AND additions to corpus were made during the NAAC three-year period | D13: 'Yes – Corpus created / strengthened' | E13: Strongest claim – shows an active corpus-building strategy
B14: a | C14: Closing corpus is greater than zero but no additions in the three years | D14: 'Yes – Corpus maintained' | E14: Option met, but explain why no additions were made
B15: a | C15: No corpus balance | D15: 'No' | E15: Do not claim the option
B16: b | C16: Investments are held in TWO OR MORE instrument categories at 31 March of the latest FY | D16: 'Yes' | E16: Supported further by number of banks and diversification index
B17: b | C17: Only one instrument category | D17: 'No' | E17: FDs in several banks alone may be argued as diversification across institutions – record the number of banks and seek clarification in the final SOP
B19: G4. STEP-BY-STEP PROCEDURE
B20: Step | C20: Activity | D20: How to do it | E20: Responsibility / Output
B21: 1 | C21: Collect audited Balance Sheets | D21: Obtain audited Balance Sheet, I&E Account and schedules for FY 2022-23 to 2025-26 | E21: Finance Office
B22: 2 | C22: Corpus schedule | D22: From the Corpus / Endowment / Reserve Fund schedule enter the opening balance of FY 2022-23 and, for each FY, the additions and withdrawals by source | E22: Finance Office – Sheet 3
B23: 3 | C23: Check closing balance | D23: Closing balance in Sheet 3 must equal the audited Balance Sheet figure; enter the audited figure in the check row | E23: Finance Office
B24: 4 | C24: Investment schedule | D24: From the Investments schedule enter holdings as at 31 March by instrument; enter number of banks/institutions and investment income | E24: Finance Office – Sheet 4
B25: 5 | C25: Revenue expenditure | D25: Enter total revenue expenditure for each FY from the Metric 4.2 workbook (used for months-of-cover) | E25: Finance Office
B26: 6 | C26: Strategies & policies | D26: Describe each strategy, the approving body (Finance Committee / BOM / Governing Body) and date; attach evidence | E26: Finance Officer & IQAC – Sheet 5
B27: 7 | C27: Review compliance | D27: Check Sheet 6 for options (a) and (b) and the indicators | E27: IQAC Director
B28: 8 | C28: CA certificate | D28: Print Sheet 9; CA verifies and signs; Registrar / Finance Officer countersigns | E28: CA & competent authority
B29: 9 | C29: Upload | D29: Select the options met on the NAAC portal; upload CA certificate and highlighted audited statements | E29: IQAC
B31: G5. CORPUS – WHAT TO INCLUDE AND EXCLUDE
B32: Item | C32: Include | D32: Exclude | E32: Where to look
B33: Corpus / Endowment Fund | C33: Funds designated as corpus, endowment, permanent fund or statutory endowment fund; general reserve earmarked as corpus by a Finance Committee / BOM resolution | D33: Unrestricted current account balances, fee received in advance, caution deposits, earmarked project funds of sponsors | E33: Balance Sheet – Corpus / Capital / Endowment Fund schedule
B34: Additions | C34: Transfer from operating surplus, sponsoring-body contribution to corpus, endowments and donations to corpus, interest earned and retained (ploughed back) in the corpus | D34: Capital grants for buildings (go to 4.1), revenue income | E34: Schedule movement; Trust/BOM resolutions
B35: Withdrawals | C35: Amounts withdrawn/utilised from the corpus for approved purposes (capital works, scholarships, contingencies) | D35: Interest transferred to I&E is not a withdrawal of principal | E35: Schedule movement; approval minutes
B37: G6. INVESTMENT CATEGORIES
B38: Code | C38: Instrument category | D38: Examples | E38: Remarks
B39: 1 | C39: Fixed deposits with scheduled banks | D39: Term deposits in nationalised / scheduled private banks | E39: Record number of banks separately – spreading across banks is itself a diversification measure
B40: 2 | C40: Government securities | D40: Central / State Government securities, treasury bills, RBI bonds | E40: Lowest risk
B41: 3 | C41: PSU / public financial institution bonds & deposits | D41: Bonds/deposits of PSUs, NABARD, SIDBI, HUDCO, PFC etc. | E41: Check permissibility under trust deed / applicable law
B42: 4 | C42: Debt mutual funds / other approved instruments | D42: Debt / liquid mutual funds, if permitted by the investment policy and applicable law | E42: Charitable trusts must follow permitted modes of investment (e.g., Section 11(5) of the Income-tax Act) – confirm with CA
B43: 5 | C43: Post office / other permitted deposits | D43: Post office deposits, other permitted schemes | E43: —
B44: 6 | C44: Others (specify) | D44: Any other instrument shown in the investment schedule | E44: Specify in Remarks
B46: G7. INDICATORS COMPUTED
B47: # | C47: Indicator | D47: Formula | E47: Meaning
...

Sheet 3. Corpus Fund
B2: SHEET 3 – CORPUS / ENDOWMENT FUND MOVEMENT (INR LAKHS)
B3: Record the year-wise movement of the Corpus / Endowment / Permanent Fund as shown in the audited Balance Sheet schedule. Enter the opening balance only for FY 2022-23; the opening balance of every later year is carried forward automatically from the previous year's closing balance. Enter additions by source and withdrawals by purpose. Source: Balance Sheet – Corpus / Endowment Fund schedule; Finance Committee / BOM resolutions.
B5: Code | C5: Particulars (INR Lakhs) | D5: FY 2025-26 | E5: FY 2024-25 | F5: FY 2023-24 | G5: FY 2022-23 | H5: NAAC 3-Yr Total (movements only) | I5: Audit Reference (Schedule / Page) | J5: Remarks
B6: A | C6: Opening balance of Corpus Fund (1 April) | D6: =E19 -> 0 | E6: =F19 -> 0 | F6: =G19 -> 0 | H6: n.a.
B7: B | C7: Add: Additions to Corpus during the year
B8: B1 | C8: Transfer from operating surplus (I&E) | H8: =SUM(D8:F8) -> 0
B9: B2 | C9: Contribution by Trust / Sponsoring body to corpus | H9: =SUM(D9:F9) -> 0
B10: B3 | C10: Endowments & donations received for corpus | H10: =SUM(D10:F10) -> 0
B11: B4 | C11: Interest / income earned and retained in corpus | H11: =SUM(D11:F11) -> 0
B12: B5 | C12: Other additions (specify in Remarks) | H12: =SUM(D12:F12) -> 0
B13: B | C13: Total Additions | D13: =SUM(D8:D12) -> 0 | E13: =SUM(E8:E12) -> 0 | F13: =SUM(F8:F12) -> 0 | G13: =SUM(G8:G12) -> 0 | H13: =SUM(H8:H12) -> 0
B14: C | C14: Less: Withdrawals / utilisation from Corpus during the year
B15: C1 | C15: Utilised for capital works / infrastructure | H15: =SUM(D15:F15) -> 0
B16: C2 | C16: Utilised for scholarships / student support | H16: =SUM(D16:F16) -> 0
B17: C3 | C17: Utilised for contingencies / other approved purposes (specify) | H17: =SUM(D17:F17) -> 0
B18: C | C18: Total Withdrawals | D18: =SUM(D15:D17) -> 0 | E18: =SUM(E15:E17) -> 0 | F18: =SUM(F15:F17) -> 0 | G18: =SUM(G15:G17) -> 0 | H18: =SUM(H15:H17) -> 0
B19: D | C19: Closing balance of Corpus Fund (31 March) = A + B – C | D19: =D6+D13-D18 -> 0 | E19: =E6+E13-E18 -> 0 | F19: =F6+F13-F18 -> 0 | G19: =G6+G13-G18 -> 0 | H19: n.a.
B21: E | C21: Verification and supporting inputs
B22: E1 | C22: Closing corpus as per audited Balance Sheet (input)
B23: E2 | C23: Difference (Workbook closing – Audited) → should be 0 | D23: =IF(D22="","-",D19-D22) -> - | E23: =IF(E22="","-",E19-E22) -> - | F23: =IF(F22="","-",F19-F22) -> - | G23: =IF(G22="","-",G19-G22) -> -
B24: E3 | C24: Verification status | D24: =IF(D22="","Enter audited figure",IF(ABS(D23)<0.01,"Matches audited BS","Check difference")) -> Enter audited figure | E24: =IF(E22="","Enter audited figure",IF(ABS(E23)<0.01,"Matches audited BS","Check difference")) -> Enter audited figure | F24: =IF(F22="","Enter audited figure",IF(ABS(F23)<0.01,"Matches audited BS","Check difference")) -> Enter audited figure | G24: =IF(G22="","Enter audited figure",IF(ABS(G23)<0.01,"Matches audited BS","Check difference")) -> Enter audited figure
B25: E4 | C25: Total Revenue Expenditure for the FY (from Metric 4.2 workbook) (input)
B27: Filling rules: (1) Enter amounts in INR Lakhs (two decimals) in cream cells only. (2) Opening balance is entered ONLY for FY 2022-23; later years carry forward automatically. (3) Enter 0 or leave blank where not applicable. (4) Give the Balance Sheet schedule/page in 'Audit Reference' for every non-zero figure. (5) Refer to Sheet 2, G5 for what counts as corpus.

Sheet 4. Investment Portfolio
B2: SHEET 4 – INVESTMENT PORTFOLIO AS AT 31 MARCH (INR LAKHS)
B3: Record investments (of corpus and surplus funds) held as at 31 March of each financial year, classified by type of instrument, as per the audited Balance Sheet investment schedule. Also enter the number of banks / institutions where funds are invested and the investment income earned during the year. Source: Balance Sheet – Investments schedule; FD register; bank confirmations; holding statements.
B5: Code | C5: Instrument category (INR Lakhs) | D5: FY 2025-26 (as at 31 Mar) | E5: FY 2024-25 (as at 31 Mar) | F5: FY 2023-24 (as at 31 Mar) | G5: FY 2022-23 (as at 31 Mar) | H5: Average (NAAC 3 Yrs) | I5: Audit Reference (Schedule / Page) | J5: Remarks
B6: 1 | C6: Fixed deposits with scheduled banks | H6: =IFERROR(AVERAGE(D6:F6),0) -> 0
B7: 2 | C7: Government securities / treasury bills / RBI bonds | H7: =IFERROR(AVERAGE(D7:F7),0) -> 0
B8: 3 | C8: PSU / public financial institution bonds & deposits | H8: =IFERROR(AVERAGE(D8:F8),0) -> 0
B9: 4 | C9: Debt mutual funds / other approved instruments | H9: =IFERROR(AVERAGE(D9:F9),0) -> 0
B10: 5 | C10: Post office / other permitted deposits | H10: =IFERROR(AVERAGE(D10:F10),0) -> 0
B11: 6 | C11: Others (specify in Remarks) | H11: =IFERROR(AVERAGE(D11:F11),0) -> 0
B12: T | C12: Total Investments as at 31 March | D12: =SUM(D6:D11) -> 0 | E12: =SUM(E6:E11) -> 0 | F12: =SUM(F6:F11) -> 0 | G12: =SUM(G6:G11) -> 0 | H12: =SUM(H6:H11) -> 0
B14: S | C14: Supporting inputs
B15: S1 | C15: Number of banks / financial institutions in which funds are invested (input)
B16: S2 | C16: Investment income earned during the year (interest, dividends, gains) (input) | H16: =SUM(D16:F16) -> 0
B17: S3 | C17: Total investments as per audited Balance Sheet (input – for verification)
B18: S4 | C18: Verification status | D18: =IF(D17="","Enter audited figure",IF(ABS(D12-D17)<0.01,"Matches audited BS","Check difference")) -> Enter audited figure | E18: =IF(E17="","Enter audited figure",IF(ABS(E12-E17)<0.01,"Matches audited BS","Check difference")) -> Enter audited figure | F18: =IF(F17="","Enter audited figure",IF(ABS(F12-F17)<0.01,"Matches audited BS","Check difference")) -> Enter audited figure | G18: =IF(G17="","Enter audited figure",IF(ABS(G12-G17)<0.01,"Matches audited BS","Check difference")) -> Enter audited figure
B20: P | C20: Portfolio share by category (auto-calculated)
B21: 1 | C21: Share – Fixed deposits with scheduled banks | D21: =IF(D12=0,"-",D6/D12) -> - | E21: =IF(E12=0,"-",E6/E12) -> - | F21: =IF(F12=0,"-",F6/F12) -> - | G21: =IF(G12=0,"-",G6/G12) -> -
B22: 2 | C22: Share – Government securities / treasury bills / RBI bonds | D22: =IF(D12=0,"-",D7/D12) -> - | E22: =IF(E12=0,"-",E7/E12) -> - | F22: =IF(F12=0,"-",F7/F12) -> - | G22: =IF(G12=0,"-",G7/G12) -> -
B23: 3 | C23: Share – PSU / public financial institution bonds & deposits | D23: =IF(D12=0,"-",D8/D12) -> - | E23: =IF(E12=0,"-",E8/E12) -> - | F23: =IF(F12=0,"-",F8/F12) -> - | G23: =IF(G12=0,"-",G8/G12) -> -
B24: 4 | C24: Share – Debt mutual funds / other approved instruments | D24: =IF(D12=0,"-",D9/D12) -> - | E24: =IF(E12=0,"-",E9/E12) -> - | F24: =IF(F12=0,"-",F9/F12) -> - | G24: =IF(G12=0,"-",G9/G12) -> -
B25: 5 | C25: Share – Post office / other permitted deposits | D25: =IF(D12=0,"-",D10/D12) -> - | E25: =IF(E12=0,"-",E10/E12) -> - | F25: =IF(F12=0,"-",F10/F12) -> - | G25: =IF(G12=0,"-",G10/G12) -> -
B26: 6 | C26: Share – Others (specify in Remarks) | D26: =IF(D12=0,"-",D11/D12) -> - | E26: =IF(E12=0,"-",E11/E12) -> - | F26: =IF(F12=0,"-",F11/F12) -> - | G26: =IF(G12=0,"-",G11/G12) -> -
B28: Filling rules: (1) Enter holdings as at 31 March (book value as per audited Balance Sheet) in cream cells. (2) Classify each investment in one category only. (3) Number of banks counts distinct banks / institutions across all categories. (4) Investment income must agree with the figure reported as revenue income in Metric 4.2. (5) Refer to Sheet 2, G6.

Sheet 5. Strategies & Policies
B2: SHEET 5 – FINANCIAL SUSTAINABILITY STRATEGIES & POLICIES
B3: Describe each strategy actually followed by the University, the body that approved it and the date, and where the evidence is filed. Select status from the drop-down. Grey italic guidance text in column D shows what to write – replace it with the University's own description. These descriptions also serve as the qualitative narrative for Metric 4.3.
B5: # | C5: Strategy | D5: Description (what the University does) | E5: Approved by (Body) | F5: Date of approval | G5: Status | H5: Evidence reference / file
B6: 1 | C6: Corpus / Endowment Fund policy [Option (a)] | D6: State the purpose of the corpus, rules for preserving principal, sources of additions and conditions for withdrawal | G6: Planned
B7: 2 | C7: Annual transfer of surplus to corpus [Option (a)] | D7: State the % or amount of operating surplus transferred to corpus each year and the resolution | G7: Planned
B8: 3 | C8: Sponsoring-body / Trust contribution to corpus [Option (a)] | D8: State the commitment of the sponsoring body and amounts contributed | G8: Planned
B9: 4 | C9: Endowments & donations mobilisation [Option (a)] | D9: Alumni, industry, CSR and philanthropic endowments; endowment chairs and scholarships | G9: Planned
B10: 5 | C10: Statutory endowment fund compliance [Option (a)] | D10: Endowment fund required under the applicable State Private Universities Act / regulator norms, if applicable | G10: Planned
B11: 6 | C11: Investment Policy [Option (b)] | D11: Permitted instruments, limits per instrument and per bank, credit-rating criteria, approval hierarchy | G11: Planned
B12: 7 | C12: Spread across banks and instruments [Option (b)] | D12: Number of banks, mix of FDs, government securities, bonds etc.; maximum exposure limits | G12: Planned
B13: 8 | C13: Periodic review of investments [Option (b)] | D13: Finance Committee / Investment Committee review frequency and decisions | G13: Planned
B14: 9 | C14: Diversification of income sources [Supporting strategy] | D14: Consultancy, training, research grants, executive programmes, CSR, alumni giving – reduces fee dependency (link to Metric 4.2) | G14: Planned
B15: 10 | C15: Cost optimisation & efficiency [Supporting strategy] | D15: Energy savings, centralised procurement, shared facilities | G15: Planned
B16: 11 | C16: Contingency / sinking fund [Supporting strategy] | D16: Reserve for loan repayment, major repairs or emergencies | G16: Planned
C17: Strategies Implemented (count) | G17: =COUNTIF(G6:G16,"Implemented")&" / "&(11-COUNTIF(G6:G16,"Not applicable")) -> 0 / 11

Sheet 6. Summary & Compliance
B2: SHEET 6 – SUMMARY, OPTION COMPLIANCE & INDICATORS
B3: This sheet is fully formula-driven from Sheets 3, 4 and 5 – do not type here. Section A shows whether options (a) and (b) can be claimed on the NAAC portal. Sections B and C give the indicators that demonstrate the strength of each strategy.
B5: A. NAAC OPTION COMPLIANCE (ASSESSMENT PERIOD FY 2023-24 TO 2025-26)
B6: Option | C6: Strategy | D6: Status for NAAC | H6: Basis
B7: (a) | C7: Creation of Corpus | D7: =IF('3. Corpus Fund'!D19>0,IF(SUM('3. Corpus Fund'!D13:F13)>0,"YES – Corpus created / strengthened","YES – Corpus maintained (no additions)"),"NO – No corpus balance") -> NO – No corpus balance | H7: Closing corpus (FY 2025-26) > 0 and additions in 3 years
B8: (b) | C8: Diversification of Investments | D8: =IF(COUNTIF('4. Investment Portfolio'!D6:D11,">0")>=2,"YES – Invested in "&COUNTIF('4. Investment Portfolio'!D6:D11,">0")&" categories across "&'4. Investment Portfolio'!D15&" banks / institutions",IF(COUNTIF('4. Investment Portfolio'!D6:D11,">0")=1,"NO – Single instrument category","NO – No investments recorded")) -> NO – No investments recorded | H8: ≥ 2 instrument categories at 31 Mar 2026
C9: Options fulfilled (out of 2) | D9: =(LEFT(D7,3)="YES")+(LEFT(D8,3)="YES")&" of 2" -> 0 of 2
B11: B. OPTION (a) – CORPUS INDICATORS (INR LAKHS)
B12: # | C12: Indicator | D12: FY 2025-26 | E12: FY 2024-25 | F12: FY 2023-24 | G12: FY 2022-23 | H12: NAAC 3-Yr
B13: B1 | C13: Opening Corpus (1 April) | D13: ='3. Corpus Fund'!D6 -> 0 | E13: ='3. Corpus Fund'!E6 -> 0 | F13: ='3. Corpus Fund'!F6 -> 0 | G13: ='3. Corpus Fund'!G6 -> 0 | H13: —
B14: B2 | C14: Additions during the year | D14: ='3. Corpus Fund'!D13 -> 0 | E14: ='3. Corpus Fund'!E13 -> 0 | F14: ='3. Corpus Fund'!F13 -> 0 | G14: ='3. Corpus Fund'!G13 -> 0 | H14: =SUM(D14:F14) -> 0
B15: B3 | C15: Withdrawals during the year | D15: ='3. Corpus Fund'!D18 -> 0 | E15: ='3. Corpus Fund'!E18 -> 0 | F15: ='3. Corpus Fund'!F18 -> 0 | G15: ='3. Corpus Fund'!G18 -> 0 | H15: =SUM(D15:F15) -> 0
B16: B4 | C16: Closing Corpus (31 March) | D16: ='3. Corpus Fund'!D19 -> 0 | E16: ='3. Corpus Fund'!E19 -> 0 | F16: ='3. Corpus Fund'!F19 -> 0 | G16: ='3. Corpus Fund'!G19 -> 0 | H16: —
B17: B5 | C17: Corpus Growth % (year-on-year) | D17: =IF(OR(E16=0,D16=0),"-",D16/E16-1) -> - | E17: =IF(OR(F16=0,E16=0),"-",E16/F16-1) -> - | F17: =IF(OR(G16=0,F16=0),"-",F16/G16-1) -> - | G17: n.a. | H17: =IF(OR(G16=0,D16=0),"-",D16/G16-1) -> -
B18: B6 | C18: Months of Operating Cover (Closing Corpus ÷ monthly revenue expenditure) | D18: =IF(N('3. Corpus Fund'!D25)=0,"-",D16/('3. Corpus Fund'!D25/12)) -> - | E18: =IF(N('3. Corpus Fund'!E25)=0,"-",E16/('3. Corpus Fund'!E25/12)) -> - | F18: =IF(N('3. Corpus Fund'!F25)=0,"-",F16/('3. Corpus Fund'!F25/12)) -> - | G18: =IF(N('3. Corpus Fund'!G25)=0,"-",G16/('3. Corpus Fund'!G25/12)) -> - | H18: —
B19: B7 | C19: Interpretation – operating cover (indicative) | D19: =IF(N(D18)=0,"Enter data",IF(D18<3,"Low (< 3 months)",IF(D18<=6,"Adequate (3–6 months)","Strong (> 6 months)"))) -> Enter data | E19: =IF(N(E18)=0,"Enter data",IF(E18<3,"Low (< 3 months)",IF(E18<=6,"Adequate (3–6 months)","Strong (> 6 months)"))) -> Enter data | F19: =IF(N(F18)=0,"Enter data",IF(F18<3,"Low (< 3 months)",IF(F18<=6,"Adequate (3–6 months)","Strong (> 6 months)"))) -> Enter data | G19: =IF(N(G18)=0,"Enter data",IF(G18<3,"Low (< 3 months)",IF(G18<=6,"Adequate (3–6 months)","Strong (> 6 months)"))) -> Enter data
B20: Note: NAAC 3-Yr growth = growth from closing FY 2022-23 to closing FY 2025-26.
B22: C. OPTION (b) – INVESTMENT DIVERSIFICATION INDICATORS
B23: # | C23: Indicator | D23: FY 2025-26 | E23: FY 2024-25 | F23: FY 2023-24 | G23: FY 2022-23 | H23: NAAC 3-Yr
B24: C1 | C24: Total Investments as at 31 March (INR Lakhs) | D24: ='4. Investment Portfolio'!D12 -> 0 | E24: ='4. Investment Portfolio'!E12 -> 0 | F24: ='4. Investment Portfolio'!F12 -> 0 | G24: ='4. Investment Portfolio'!G12 -> 0 | H24: —
B25: C2 | C25: Number of instrument categories held | D25: =COUNTIF('4. Investment Portfolio'!D6:D11,">0") -> 0 | E25: =COUNTIF('4. Investment Portfolio'!E6:E11,">0") -> 0 | F25: =COUNTIF('4. Investment Portfolio'!F6:F11,">0") -> 0 | G25: =COUNTIF('4. Investment Portfolio'!G6:G11,">0") -> 0 | H25: —
B26: C3 | C26: Number of banks / institutions | D26: =N('4. Investment Portfolio'!D15) -> 0 | E26: =N('4. Investment Portfolio'!E15) -> 0 | F26: =N('4. Investment Portfolio'!F15) -> 0 | G26: =N('4. Investment Portfolio'!G15) -> 0 | H26: —
B27: C4 | C27: Largest category share % (concentration) | D27: =IF(D24=0,"-",MAX('4. Investment Portfolio'!D6:D11)/D24) -> - | E27: =IF(E24=0,"-",MAX('4. Investment Portfolio'!E6:E11)/E24) -> - | F27: =IF(F24=0,"-",MAX('4. Investment Portfolio'!F6:F11)/F24) -> - | G27: =IF(G24=0,"-",MAX('4. Investment Portfolio'!G6:G11)/G24) -> - | H27: —
B28: C5 | C28: Diversification Index (1 – Σ share²) | D28: =IF(D24=0,"-",1-SUMPRODUCT('4. Investment Portfolio'!D6:D11,'4. Investment Portfolio'!D6:D11)/D24^2) -> - | E28: =IF(E24=0,"-",1-SUMPRODUCT('4. Investment Portfolio'!E6:E11,'4. Investment Portfolio'!E6:E11)/E24^2) -> - | F28: =IF(F24=0,"-",1-SUMPRODUCT('4. Investment Portfolio'!F6:F11,'4. Investment Portfolio'!F6:F11)/F24^2) -> - | G28: =IF(G24=0,"-",1-SUMPRODUCT('4. Investment Portfolio'!G6:G11,'4. Investment Portfolio'!G6:G11)/G24^2) -> - | H28: —
B29: C6 | C29: Interpretation – diversification (indicative) | D29: =IF(D24=0,"Enter data",IF(D28<0.3,"Concentrated (< 0.30)",IF(D28<=0.6,"Moderate (0.30–0.60)","Well diversified (> 0.60)"))) -> Enter data | E29: =IF(E24=0,"Enter data",IF(E28<0.3,"Concentrated (< 0.30)",IF(E28<=0.6,"Moderate (0.30–0.60)","Well diversified (> 0.60)"))) -> Enter data | F29: =IF(F24=0,"Enter data",IF(F28<0.3,"Concentrated (< 0.30)",IF(F28<=0.6,"Moderate (0.30–0.60)","Well diversified (> 0.60)"))) -> Enter data | G29: =IF(G24=0,"Enter data",IF(G28<0.3,"Concentrated (< 0.30)",IF(G28<=0.6,"Moderate (0.30–0.60)","Well diversified (> 0.60)"))) -> Enter data
B30: C7 | C30: Option (b) met in the year? (≥ 2 categories) | D30: =IF(D25>=2,"Yes","No") -> No | E30: =IF(E25>=2,"Yes","No") -> No | F30: =IF(F25>=2,"Yes","No") -> No | G30: =IF(G25>=2,"Yes","No") -> No | H30: —
B31: C8 | C31: Investment income (INR Lakhs) | D31: ='4. Investment Portfolio'!D16 -> 0 | E31: ='4. Investment Portfolio'!E16 -> 0 | F31: ='4. Investment Portfolio'!F16 -> 0 | G31: ='4. Investment Portfolio'!G16 -> 0 | H31: =SUM(D31:F31) -> 0
B32: C9 | C32: Investment Yield % (income ÷ year-end investments) | D32: =IF(D24=0,"-",D31/D24) -> - | E32: =IF(E24=0,"-",E31/E24) -> - | F32: =IF(F24=0,"-",F31/F24) -> - | G32: =IF(G24=0,"-",G31/G24) -> - | H32: —
B33: C10 | C33: Investments as multiple of Closing Corpus | D33: =IF(D16=0,"-",D24/D16) -> - | E33: =IF(E16=0,"-",E24/E16) -> - | F33: =IF(F16=0,"-",F24/F16) -> - | G33: =IF(G16=0,"-",G24/G16) -> - | H33: —
B35: D. SUPPORTING STRATEGIES (FROM SHEET 5)
B36: D1 | C36: Strategies implemented (count) | D36: ='5. Strategies & Policies'!G17 -> 0 / 11
B38: E. CHART – CLOSING CORPUS AND TOTAL INVESTMENTS
B63: Reading the results: Claim option (a) when a designated corpus exists in the audited Balance Sheet, and preferably show that it has grown during the assessment period. Claim option (b) when investments are spread over two or more instrument categories under an approved investment policy. A rising corpus, more than six months of operating cover and a diversification index above 0.60 together present a strong sustainability case.

Sheet 7. Worked Example
B2: SHEET 7 – WORKED EXAMPLE (HYPOTHETICAL FIGURES – FOR UNDERSTANDING ONLY)
B3: The figures below are purely illustrative and do NOT represent any institution's accounts. Revenue expenditure figures are the same as in the Metric 4.2 worked example, so the three workbooks tell one consistent story.
B5: Step 1 – Corpus movement
B6: Code | C6: Particulars (INR Lakhs) | D6: FY 2025-26 | E6: FY 2024-25 | F6: FY 2023-24 | G6: FY 2022-23 | H6: NAAC 3-Yr
B7: A | C7: Opening Corpus | D7: =E14 -> 5410 | E7: =F14 -> 3950 | F7: =G14 -> 2890 | G7: 2000
B8: B1 | C8: Transfer from operating surplus | D8: 1200 | E8: 1000 | F8: 700 | G8: 500 | H8: =SUM(D8:F8) -> 2900
B9: B2 | C9: Trust / sponsoring-body contribution | D9: 300 | E9: 250 | F9: 200 | G9: 200 | H9: =SUM(D9:F9) -> 750
B10: B3 | C10: Endowments & donations | D10: 100 | E10: 80 | F10: 60 | G10: 50 | H10: =SUM(D10:F10) -> 240
B11: B4 | C11: Interest retained in corpus | D11: 380 | E11: 280 | F11: 200 | G11: 140 | H11: =SUM(D11:F11) -> 860
B12: B | C12: Total Additions | D12: =SUM(D8:D11) -> 1980 | E12: =SUM(E8:E11) -> 1610 | F12: =SUM(F8:F11) -> 1160 | G12: =SUM(G8:G11) -> 890 | H12: =SUM(H8:H11) -> 4750
B13: C | C13: Withdrawals (scholarships / capital works) | D13: 200 | E13: 150 | F13: 100 | G13: 0 | H13: =SUM(D13:F13) -> 450
B14: D | C14: Closing Corpus = A + B – C | D14: =D7+D12-D13 -> 7190 | E14: =E7+E12-E13 -> 5410 | F14: =F7+F12-F13 -> 3950 | G14: =G7+G12-G13 -> 2890
B15: E | C15: Revenue expenditure (from 4.2 example) | D15: 8700 | E15: 8000 | F15: 7330 | G15: 6690
B16: F | C16: Months of operating cover | D16: =IF(D15=0,"-",D14/(D15/12)) -> 9.9172414 | E16: =IF(E15=0,"-",E14/(E15/12)) -> 8.115 | F16: =IF(F15=0,"-",F14/(F15/12)) -> 6.4665757 | G16: =IF(G15=0,"-",G14/(G15/12)) -> 5.1838565
B18: Step 2 – Investment portfolio as at 31 March
B19: Code | C19: Particulars (INR Lakhs) | D19: FY 2025-26 | E19: FY 2024-25 | F19: FY 2023-24 | G19: FY 2022-23 | H19: NAAC 3-Yr
B20: 1 | C20: Fixed deposits (scheduled banks) | D20: 4500 | E20: 4000 | F20: 3500 | G20: 3200
B21: 2 | C21: Government securities | D21: 1500 | E21: 1100 | F21: 600 | G21: 200
B22: 3 | C22: PSU bonds | D22: 800 | E22: 600 | F22: 300 | G22: 0
B23: 4 | C23: Debt mutual funds | D23: 900 | E23: 500 | F23: 200 | G23: 0
B24: 5 | C24: Post office / others | D24: 300 | E24: 200 | F24: 100 | G24: 0
B25: T | C25: Total Investments | D25: =SUM(D20:D24) -> 8000 | E25: =SUM(E20:E24) -> 6400 | F25: =SUM(F20:F24) -> 4700 | G25: =SUM(G20:G24) -> 3400
B26: S1 | C26: Number of banks / institutions | D26: 6 | E26: 5 | F26: 4 | G26: 3
B27: S2 | C27: Investment income | D27: 560 | E27: 450 | F27: 340 | G27: 250 | H27: =SUM(D27:F27) -> 1350
B29: Step 3 – Results
B30: # | C30: Indicator | D30: FY 2025-26 | E30: FY 2024-25 | F30: FY 2023-24 | G30: FY 2022-23
B31: a | C31: Corpus growth % (year-on-year) | D31: =D14/E14-1 -> 0.32902033 | E31: =E14/F14-1 -> 0.36962025 | F31: =F14/G14-1 -> 0.36678201 | G31: n.a.
B32: b | C32: Number of instrument categories | D32: =COUNTIF(D20:D24,">0") -> 5 | E32: =COUNTIF(E20:E24,">0") -> 5 | F32: =COUNTIF(F20:F24,">0") -> 5 | G32: =COUNTIF(G20:G24,">0") -> 2
B33: c | C33: Largest category share % | D33: =MAX(D20:D24)/D25 -> 0.5625 | E33: =MAX(E20:E24)/E25 -> 0.625 | F33: =MAX(F20:F24)/F25 -> 0.74468085 | G33: =MAX(G20:G24)/G25 -> 0.94117647
B34: d | C34: Diversification Index (1 – Σ share²) | D34: =1-SUMPRODUCT(D20:D24,D20:D24)/D25^2 -> 0.624375 | E34: =1-SUMPRODUCT(E20:E24,E20:E24)/E25^2 -> 0.56396484 | F34: =1-SUMPRODUCT(F20:F24,F20:F24)/F25^2 -> 0.42281575 | G34: =1-SUMPRODUCT(G20:G24,G20:G24)/G25^2 -> 0.11072664
B35: e | C35: Investment yield % | D35: =D27/D25 -> 0.07 | E35: =E27/E25 -> 0.0703125 | F35: =F27/F25 -> 0.072340426 | G35: =G27/G25 -> 0.073529412
B36: f | C36: Option (a) / (b) status | D36: =IF(D14>0,"(a) Yes","(a) No")&" | "&IF(COUNTIF(D20:D24,">0")>=2,"(b) Yes","(b) No") -> (a) Yes | (b) Yes | E36: =IF(E14>0,"(a) Yes","(a) No")&" | "&IF(COUNTIF(E20:E24,">0")>=2,"(b) Yes","(b) No") -> (a) Yes | (b) Yes | F36: =IF(F14>0,"(a) Yes","(a) No")&" | "&IF(COUNTIF(F20:F24,">0")>=2,"(b) Yes","(b) No") -> (a) Yes | (b) Yes | G36: =IF(G14>0,"(a) Yes","(a) No")&" | "&IF(COUNTIF(G20:G24,">0")>=2,"(b) Yes","(b) No") -> (a) Yes | (b) Yes
B38: How to read this example
B39: 1. Option (a): The corpus grew from 2,890 Lakhs (31 Mar 2023) to 7,190 Lakhs (31 Mar 2026) – about 2.5 times – mainly through annual transfer of operating surplus. At 31 Mar 2026 it covers about 9.9 months of running costs (Strong). Claim: 'YES – Corpus created / strengthened'. 2. Option (b): In FY 2022-23 funds were in only two categories, mostly FDs (94% concentration). By FY 2025-26 they are spread across five categories and six banks; FD share fell to about 56% and the diversification index rose from about 0.11 to about 0.62 (well diversified). Claim: 'YES'. 3. Investment yield of about 7% shows the funds are productively deployed; this income appears as revenue income in Metric 4.2. 4. In the narrative, link the story: operating surplus (Metric 4.2) → transfer to corpus (4.3a) → invested across instruments under an approved policy (4.3b) → investments reviewed by Finance Committee (Metric 4.4).

Sheet 8. Document Checklist
B2: SHEET 8 – SUPPORTING DOCUMENT CHECKLIST
B3: Select the status for each document and financial year (Available / Pending / Not Applicable). Items 1 and 2 are mandatory as per NAAC; the rest are recommended evidence for Data Validation & Verification (DVV).
B5: # | C5: Document | D5: Purpose / What to highlight | E5: FY 2025-26 | F5: FY 2024-25 | G5: FY 2023-24 | H5: FY 2022-23 | I5: Responsibility | J5: File name / Link / Remarks
B6: 1 | C6: Audited Income & Expenditure statement and Balance Sheet – certified by CA (MANDATORY) | D6: Highlight Corpus Fund and Investments schedules | E6: Pending | F6: Pending | G6: Pending | H6: Pending | I6: Finance Officer
B7: 2 | C7: CA-certified audit extract of corpus and investments (MANDATORY – Sheet 9 format) | D7: Must match Sheet 6 | E7: Pending | F7: Pending | G7: Pending | H7: Pending | I7: CA / Finance Officer
B8: 3 | C8: Corpus / Endowment Fund policy | D8: Purpose, preservation of principal, additions and withdrawals rules | E8: Pending | F8: Pending | G8: Pending | H8: Pending | I8: Finance Officer
B9: 4 | C9: Resolutions for transfer of surplus / contribution to corpus | D9: Amount and date for each FY | E9: Pending | F9: Pending | G9: Pending | H9: Pending | I9: Registrar / Finance
B10: 5 | C10: Investment Policy approved by Finance Committee / BOM | D10: Permitted instruments, limits, review | E10: Pending | F10: Pending | G10: Pending | H10: Pending | I10: Finance Officer
B11: 6 | C11: FD receipts / bank confirmations as at 31 March | D11: Supports investment schedule | E11: Pending | F11: Pending | G11: Pending | H11: Pending | I11: Finance Office
B12: 7 | C12: Holding / demat statements for securities, bonds, mutual funds | D12: Supports investment schedule | E12: Pending | F12: Pending | G12: Pending | H12: Pending | I12: Finance Office
B13: 8 | C13: Finance Committee / Investment Committee minutes | D13: Review of corpus and investments | E13: Pending | F13: Pending | G13: Pending | H13: Pending | I13: Registrar
B14: 9 | C14: Statutory endowment fund compliance (if applicable) | D14: Proof of required endowment | E14: Pending | F14: Pending | G14: Pending | H14: Pending | I14: Registrar / Finance
B15: 10 | C15: Endowment / donation deeds | D15: Corpus additions from endowments | E15: Pending | F15: Pending | G15: Pending | H15: Pending | I15: Finance Office
B16: 11 | C16: Explanatory note (if option not fully met or no additions) | D16: Reasons and plan | E16: Pending | F16: Pending | G16: Pending | H16: Pending | I16: IQAC & Finance Officer
C17: Documents Available (count) | E17: =COUNTIF(E6:E16,"Available")&" / "&(11-COUNTIF(E6:E16,"Not Applicable")) -> 0 / 11 | F17: =COUNTIF(F6:F16,"Available")&" / "&(11-COUNTIF(F6:F16,"Not Applicable")) -> 0 / 11 | G17: =COUNTIF(G6:G16,"Available")&" / "&(11-COUNTIF(G6:G16,"Not Applicable")) -> 0 / 11 | H17: =COUNTIF(H6:H16,"Available")&" / "&(11-COUNTIF(H6:H16,"Not Applicable")) -> 0 / 11

Sheet 9. CA Certificate
B2: CERTIFICATE BY CHARTERED ACCOUNTANT
B3: (To be printed on the letterhead of the Chartered Accountant firm)
B5: Ref. No.: ____________________ Date: ____________________
B6: Sub.: Certificate of Corpus Fund and Investments of [University Name] for NAAC Metric 4.3 – Sustainability (Binary Accreditation Framework) – Financial Years 2022-23 to 2025-26
B8: This is to certify that we have verified the audited Balance Sheets, Income & Expenditure Accounts and related schedules of [University Name] for the financial years mentioned below. Based on our verification, the movement of the Corpus / Endowment Fund and the investments held as at 31 March of each year are as under:
B10: S. No. | C10: Financial Year | D10: Additions to Corpus (INR Lakhs) | E10: Closing Corpus (INR Lakhs) | F10: Total Investments (INR Lakhs) | G10: No. of Investment Categories
B11: 1 | C11: FY 2025-26 | D11: ='6. Summary & Compliance'!D14 -> 0 | E11: ='6. Summary & Compliance'!D16 -> 0 | F11: ='6. Summary & Compliance'!D24 -> 0 | G11: ='6. Summary & Compliance'!D25 -> 0
B12: 2 | C12: FY 2024-25 | D12: ='6. Summary & Compliance'!E14 -> 0 | E12: ='6. Summary & Compliance'!E16 -> 0 | F12: ='6. Summary & Compliance'!E24 -> 0 | G12: ='6. Summary & Compliance'!E25 -> 0
B13: 3 | C13: FY 2023-24 | D13: ='6. Summary & Compliance'!F14 -> 0 | E13: ='6. Summary & Compliance'!F16 -> 0 | F13: ='6. Summary & Compliance'!F24 -> 0 | G13: ='6. Summary & Compliance'!F25 -> 0
B14: 4 | C14: FY 2022-23 | D14: ='6. Summary & Compliance'!G14 -> 0 | E14: ='6. Summary & Compliance'!G16 -> 0 | F14: ='6. Summary & Compliance'!G24 -> 0 | G14: ='6. Summary & Compliance'!G25 -> 0
B16: We further certify that (i) the Corpus / Endowment Fund is shown separately in the audited Balance Sheets and its closing balances agree with the figures above; (ii) the investments are held in the name of the University / sponsoring body for the University and are classified as per the investment schedule of the audited accounts; and (iii) the relevant components have been highlighted in the audited statements enclosed herewith.
B19: For ____________________ (CA Firm Name) | E19: Countersigned by
B20: Chartered Accountants, FRN: __________ | E20: Registrar / Finance Officer
E21: [University Name]
B22: (Signature & Seal) | E22: (Signature & Seal)
B23: Name of Partner: ____________________
B24: Membership No.: __________ UDIN: __________
B26: Place: [City] Enclosures: Highlighted audited Balance Sheets and I&E statements for FY 2022-23, 2023-24, 2024-25 and 2025-26
