Workbook

Sheet 1. Cover
B2: [UNIVERSITY NAME]
B3: Internal Quality Assurance Cell (IQAC)
B5: NAAC Binary Accreditation Framework | Attribute 4 – Financial Resources & Management (50)
B6: Metric 4.2 – Ratio of Revenue Income vs Revenue Expenditure (Weightage: 15)
B7: Data Capture, Computation & Evidence Workbook • Financial Years 2025-26, 2024-25, 2023-24 and 2022-23 • All amounts in INR Lakhs
B9: ABSTRACT
B10: This workbook is the institutional tool for preparing NAAC Metric 4.2 – Ratio of Revenue Income vs Revenue Expenditure. It captures, head-wise, every recurring (revenue) income of the University – fees, R&D grants, salary grants, alumni contribution, consultancy, endowment income, scholarships and other operating receipts – and every recurring (revenue) expenditure – salaries, maintenance, administration, scholarships & assistance, electricity, transport, career guidance & skilling, employee benefits and extracurricular / co-curricular activities – for four financial years: 2025-26, 2024-25, 2023-24 and 2022-23. All totals, ratios and interpretations are calculated automatically. The Summary sheet reproduces the figures in the exact NAAC data-template format for the three-year assessment period (FY 2023-24 to 2025-26), with FY 2022-23 retained as a baseline year for trend analysis. Guidelines, a worked example, an evidence checklist and a Chartered Accountant (CA) certificate format are included so that the figures submitted are complete, consistent with Metric 4.1 and Metric 3.2, and fully traceable to audited accounts.
B12: INTRODUCTION
B13: Why this metric matters: Metric 4.2 tests the operational financial health of the institution – whether its day-to-day income is sufficient to meet its day-to-day running costs. An institution whose revenue income consistently covers its revenue expenditure is self-sustaining, can pay salaries and maintain services without depending on borrowings, and can generate a surplus for reinvestment in infrastructure (Metric 4.1) and corpus (Metric 4.3). What is compared: • Revenue Income – recurring income from fees, R&D grants, salary grants, alumni contribution, consultancy, endowments, scholarships etc. • Revenue Expenditure – recurring spending on salaries, maintenance, administration, scholarships & assistance, electricity, transport, career guidance & skilling, employee benefits, extracurricular and co-curricular activities etc. How it is presented: For each financial year, NAAC asks for (1) the total revenue income and (2) the total revenue expenditure, both in INR Lakhs, supported by audited statements certified by a CA and countersigned by the competent authority. Link with other metrics: Metric 4.2 covers only revenue (recurring) items. Capital receipts and asset creation belong to Metric 4.1. Revenue expenditure excluding salaries feeds into 'Total expenditure excluding salary' used in Metric 3.2.
B15: OBJECTIVES OF THIS WORKBOOK
B16: 1. Provide a single, standard format for recording revenue income and expenditure head-wise for four financial years. 2. Compute the Revenue Coverage Ratio, operating surplus/deficit, surplus margin, fee dependency, salary share and year-on-year growth automatically. 3. Generate the NAAC data-template values for the assessment period without manual re-typing. 4. Provide the 'expenditure excluding salary' figure needed for Metric 3.2. 5. Link every figure to its source in the audited accounts and track all supporting documents.
B18: WORKBOOK STRUCTURE
B19: Sheet | C19: Purpose | D19: Who fills / uses | E19: Action required
B20: 1. Cover | C20: Abstract, introduction, objectives and structure | D20: All users | E20: Read first
B21: 2. Guidelines | C21: Definitions, include/exclude rules, procedure, formulas, interpretation bands, documents and common errors | D21: Finance Office & IQAC | E21: Read before entering data
B22: 3. Revenue Income | C22: Head-wise recurring income for each FY with audit reference | D22: Finance Office | E22: Enter figures in cream cells
B23: 4. Revenue Expenditure | C23: Head-wise recurring expenditure for each FY with audit reference | D23: Finance Office | E23: Enter figures in cream cells
B24: 5. Summary & Ratio | C24: NAAC data template, ratios, interpretation, composition, 3.2 linkage and chart | D24: IQAC (auto-calculated) | E24: Review only – no entry
B25: 6. Worked Example | C25: Illustration with hypothetical figures explaining how to read the results | D25: Training / reference | E25: Read only
B26: 7. Document Checklist | C26: Status of every supporting document, FY-wise | D26: IQAC & Finance Office | E26: Select status from drop-down
B27: 8. CA Certificate | C27: Certificate format pre-filled from the Summary, for CA signature | D27: CA / Finance Officer | E27: Print, verify and sign
B29: CELL COLOUR LEGEND
B30: Cream fill, blue text | C30: Input cell – enter data here (INR Lakhs, two decimals)
B31: Light navy fill, black text | C31: Formula / subtotal – do not overwrite
B32: Green text | C32: Value linked from another sheet – do not overwrite
B33: Navy fill, gold/white text | C33: Headings and sections
B35: Prepared by: IQAC, [University Name] | Version 1.0 | Basis: NAAC Binary Accreditation Framework – Metrics for Manual (Base), Draft Version
B36: Note: The NAAC draft names the ratio but does not publish a scoring formula or bands. Interpretation bands in this workbook are indicative IQAC guidance; update them when NAAC notifies the final SOP.

Sheet 2. Guidelines
B2: GUIDELINES FOR PREPARING METRIC 4.2
B3: G1. ASSESSMENT PERIOD AND YEAR BASIS
B4: • Use FINANCIAL YEARS (1 April – 31 March), not academic years. • NAAC assessment period = last three completed financial years: FY 2025-26 (Year-3, latest), FY 2024-25 (Year-2) and FY 2023-24 (Year-1). • FY 2022-23 is captured as a baseline year for trend analysis and as a reserve in case the notified window differs. It is NOT included in the NAAC three-year totals. • All amounts in INR Lakhs, rounded to two decimals (₹1,00,000 = 1.00 Lakh). • Take figures from the audited Income & Expenditure Account (accrual basis) for consistency with the CA certificate.
B6: G2. STEP-BY-STEP PROCEDURE
B7: Step | C7: Activity | D7: How to do it | E7: Responsibility / Output
B8: 1 | C8: Collect audited accounts | D8: Obtain audited Income & Expenditure Account with all income and expenditure schedules for each of the four FYs | E8: Finance Office – signed audited statements
B9: 2 | C9: List revenue income | D9: Take every income line from the I&E Account; exclude capital receipts (they belong to 4.1) | E9: Finance Office – working list
B10: 3 | C10: Classify income | D10: Map each income line to one head in Sheet 3 using G3 | E10: Finance Office
B11: 4 | C11: List revenue expenditure | D11: Take every expenditure line from the I&E Account; exclude depreciation, provisions and capital items | E11: Finance Office – working list
B12: 5 | C12: Classify expenditure | D12: Map each line to one head in Sheet 4 using G4. Count every rupee once only | E12: Finance Office
B13: 6 | C13: Enter data | D13: Type figures in cream cells only; write the schedule/page reference in 'Audit Reference' | E13: Finance Office
B14: 7 | C14: Reconcile | D14: Check Sheet 5 Section E – totals must reconcile with the audited I&E Account after the stated exclusions | E14: Finance Office & IQAC
B15: 8 | C15: Review results | D15: Check ratios, interpretation and consistency with 4.1 and 3.2 | E15: IQAC Director
B16: 9 | C16: Obtain CA certificate | D16: Print Sheet 8; CA verifies and signs; Registrar / Finance Officer countersigns | E16: CA & competent authority
B17: 10 | C17: Upload | D17: Enter Section A values on the NAAC portal; upload CA certificate and highlighted audited statements | E17: IQAC
B19: G3. REVENUE INCOME – WHAT TO INCLUDE AND EXCLUDE
B20: Code | C20: Head | D20: Include | E20: Exclude / Where to look
B21: A | C21: Fees | D21: Tuition, development, examination, admission, hostel, mess and transport fees and other student fees (net of refunds) | E21: Exclude fee received in advance for the next FY; avoid double counting with government fee reimbursement (see Head G). Source: fee schedule of I&E
B22: B | C22: R&D grants | D22: Recurring research project grants and institutional overheads from funding agencies, recognised as income in the FY | E22: Exclude grants for equipment/buildings (go to 4.1). Source: sponsored-project ledger
B23: C | C23: Salary grants | D23: Government grants received towards salaries (if any) | E23: Not usually applicable to a self-financed private university – enter 0
B24: D | C24: Alumni contribution | D24: Alumni donations for recurring purposes (events, scholarships, prizes) | E24: Exclude alumni donations for capital assets (go to 4.1)
B25: E | C25: Consultancy & training | D25: Consultancy fees, testing charges, MDP/EDP/FDP and corporate training fees | E25: Exclude amounts passed on to faculty as share if accounts show them net. Must reconcile with Metric 9.7
B26: F | C26: Endowment income | D26: Interest/income earned on endowment funds and credited to I&E | E26: Exclude the endowment principal (capital)
B27: G | C27: Scholarships received | D27: Government / external scholarships and fee reimbursements received by the institution (e.g., Post-Matric, EBC, State schemes) | E27: Do not count again if already included in Fees (Head A) – show in one head only
B28: H | C28: Other revenue income | D28: Interest on investments/FDs, rent from facilities, sale of forms, application fees, miscellaneous income | E28: Exclude profit on sale of assets (non-recurring) unless shown in I&E as income; mention in Remarks
B30: G4. REVENUE EXPENDITURE – WHAT TO INCLUDE AND EXCLUDE
B31: Code | C31: Head | D31: Include | E31: Exclude / Where to look
B32: 1 | C32: Salaries | D32: Salaries and wages of teaching, non-teaching and contract staff, visiting faculty honorarium | E32: Exclude employer PF/gratuity/insurance – enter in Head 8
B33: 2 | C33: Maintenance | D33: Repairs and maintenance of buildings, labs, equipment, IT, AMC, housekeeping, security, gardening | E33: Exclude any item capitalised in the Fixed Asset Schedule (goes to 4.1)
B34: 3 | C34: Administration | D34: Printing, stationery, postage, telephone, internet, legal and professional fees, audit fees, advertisement, insurance of assets, accreditation/ranking fees | E34: Exclude depreciation and provisions
B35: 4 | C35: Scholarships & assistance | D35: Fee waivers / freeships, merit and need-based scholarships and financial assistance given from institutional funds | E35: Exclude government scholarships merely passed through to students (unless shown as income in Head G)
B36: 5 | C36: Electricity & utilities | D36: Electricity, water charges, fuel for generators | E36: Exclude solar plant cost (capital)
B37: 6 | C37: Transport | D37: Bus hire, fuel, vehicle maintenance, drivers' wages (if not in salaries) | E37: Exclude purchase of vehicles (capital)
B38: 7 | C38: Career guidance & skilling | D38: Placement cell, training & placement activities, aptitude/soft-skill/certification programmes for students | E38: Check consistency with Metric 7.6 evidence
B39: 8 | C39: Employee benefits | D39: Employer PF, ESI, gratuity, leave encashment, group medical/life insurance, FDP/conference sponsorship, staff welfare | E39: Exclude provisions not actually incurred if accounts allow separate identification
B40: 9 | C40: Extracurricular & co-curricular | D40: Cultural, sports, technical fests, clubs, NSS/NCC, IKS, value-education and wellbeing activities | E40: Exclude purchase of sports infrastructure (capital)
B41: 10 | C41: Other revenue expenditure | D41: Library periodical subscriptions (revenue), examination expenses, convocation, hostel/mess running, interest on loans, rent (if NOT counted in 4.1), miscellaneous | E41: Exclude depreciation, asset write-offs and any rent already reported in 4.1
B43: G5. FORMULAS USED IN THIS WORKBOOK
B44: # | C44: Indicator | D44: Formula | E44: Meaning
B45: 1 | C45: Total Revenue Income | D45: A + B + C + D + E + F + G + H | E45: Total amount earned through fees, grants, consultancy, endowments, scholarships etc.
...

Sheet 3. Revenue Income
B2: SHEET 3 – REVENUE INCOME (INR LAKHS)
B3: Record the REVENUE (recurring) income earned in each financial year from fees, R&D grants, salary grants, alumni contribution, consultancy, endowments, scholarships and other operating sources. Source: Income & Expenditure Account and income schedules (audited). Do NOT include capital receipts such as loans, trust contributions for infrastructure or capital grants – these belong to Metric 4.1.
B5: Code | C5: Head / Sub-head (INR Lakhs) | D5: FY 2025-26 | E5: FY 2024-25 | F5: FY 2023-24 | G5: FY 2022-23 | H5: NAAC 3-Yr Total (FY 23-24 to 25-26) | I5: 4-Yr Total (FY 22-23 to 25-26) | J5: Audit Reference (Schedule / Page) | K5: Remarks
B6: A | C6: Fees
B7: A1 | C7: Tuition fees | H7: =SUM(D7:F7) -> 0 | I7: =SUM(D7:G7) -> 0
B8: A2 | C8: Development / other academic fees | H8: =SUM(D8:F8) -> 0 | I8: =SUM(D8:G8) -> 0
B9: A3 | C9: Examination & admission-related fees | H9: =SUM(D9:F9) -> 0 | I9: =SUM(D9:G9) -> 0
B10: A4 | C10: Hostel, mess & transport fees | H10: =SUM(D10:F10) -> 0 | I10: =SUM(D10:G10) -> 0
C11: Sub-total A – Fees | D11: =SUM(D7:D10) -> 0 | E11: =SUM(E7:E10) -> 0 | F11: =SUM(F7:F10) -> 0 | G11: =SUM(G7:G10) -> 0 | H11: =SUM(H7:H10) -> 0 | I11: =SUM(I7:I10) -> 0
B12: B | C12: R&D Grants
B13: B1 | C13: Research project grants (recurring) & overheads – Government | H13: =SUM(D13:F13) -> 0 | I13: =SUM(D13:G13) -> 0
B14: B2 | C14: Research project grants (recurring) & overheads – Non-Government | H14: =SUM(D14:F14) -> 0 | I14: =SUM(D14:G14) -> 0
C15: Sub-total B – R&D Grants | D15: =SUM(D13:D14) -> 0 | E15: =SUM(E13:E14) -> 0 | F15: =SUM(F13:F14) -> 0 | G15: =SUM(G13:G14) -> 0 | H15: =SUM(H13:H14) -> 0 | I15: =SUM(I13:I14) -> 0
B16: C | C16: Salary Grants
B17: C1 | C17: Government salary grants (if any) | H17: =SUM(D17:F17) -> 0 | I17: =SUM(D17:G17) -> 0
C18: Sub-total C – Salary Grants | D18: =SUM(D17:D17) -> 0 | E18: =SUM(E17:E17) -> 0 | F18: =SUM(F17:F17) -> 0 | G18: =SUM(G17:G17) -> 0 | H18: =SUM(H17:H17) -> 0 | I18: =SUM(I17:I17) -> 0
B19: D | C19: Alumni Contribution
B20: D1 | C20: Alumni contributions for recurring purposes | H20: =SUM(D20:F20) -> 0 | I20: =SUM(D20:G20) -> 0
C21: Sub-total D – Alumni Contribution | D21: =SUM(D20:D20) -> 0 | E21: =SUM(E20:E20) -> 0 | F21: =SUM(F20:F20) -> 0 | G21: =SUM(G20:G20) -> 0 | H21: =SUM(H20:H20) -> 0 | I21: =SUM(I20:I20) -> 0
B22: E | C22: Consultancy & Training
B23: E1 | C23: Consultancy fees & testing charges | H23: =SUM(D23:F23) -> 0 | I23: =SUM(D23:G23) -> 0
B24: E2 | C24: Training programmes (MDP / EDP / FDP / corporate) | H24: =SUM(D24:F24) -> 0 | I24: =SUM(D24:G24) -> 0
C25: Sub-total E – Consultancy & Training | D25: =SUM(D23:D24) -> 0 | E25: =SUM(E23:E24) -> 0 | F25: =SUM(F23:F24) -> 0 | G25: =SUM(G23:G24) -> 0 | H25: =SUM(H23:H24) -> 0 | I25: =SUM(I23:I24) -> 0
B26: F | C26: Endowment Income
B27: F1 | C27: Interest / income on endowment funds | H27: =SUM(D27:F27) -> 0 | I27: =SUM(D27:G27) -> 0
C28: Sub-total F – Endowment Income | D28: =SUM(D27:D27) -> 0 | E28: =SUM(E27:E27) -> 0 | F28: =SUM(F27:F27) -> 0 | G28: =SUM(G27:G27) -> 0 | H28: =SUM(H27:H27) -> 0 | I28: =SUM(I27:I27) -> 0
B29: G | C29: Scholarships Received
B30: G1 | C30: Government scholarships / fee reimbursement received | H30: =SUM(D30:F30) -> 0 | I30: =SUM(D30:G30) -> 0
B31: G2 | C31: Other external scholarships received | H31: =SUM(D31:F31) -> 0 | I31: =SUM(D31:G31) -> 0
C32: Sub-total G – Scholarships Received | D32: =SUM(D30:D31) -> 0 | E32: =SUM(E30:E31) -> 0 | F32: =SUM(F30:F31) -> 0 | G32: =SUM(G30:G31) -> 0 | H32: =SUM(H30:H31) -> 0 | I32: =SUM(I30:I31) -> 0
B33: H | C33: Other Revenue Income (specify in Remarks)
B34: H1 | C34: Interest on investments / fixed deposits | H34: =SUM(D34:F34) -> 0 | I34: =SUM(D34:G34) -> 0
B35: H2 | C35: Rent / hire of facilities | H35: =SUM(D35:F35) -> 0 | I35: =SUM(D35:G35) -> 0
B36: H3 | C36: Miscellaneous income | H36: =SUM(D36:F36) -> 0 | I36: =SUM(D36:G36) -> 0
C37: Sub-total H – Other Revenue Income (specify in Remarks) | D37: =SUM(D34:D36) -> 0 | E37: =SUM(E34:E36) -> 0 | F37: =SUM(F34:F36) -> 0 | G37: =SUM(G34:G36) -> 0 | H37: =SUM(H34:H36) -> 0 | I37: =SUM(I34:I36) -> 0
B38: TOTAL | C38: Total amount earned through Fees, R&D grants, Salary Grants, Alumni contribution, Consultancy, Endowments, Scholarships etc. | D38: =D11+D15+D18+D21+D25+D28+D32+D37 -> 0 | E38: =E11+E15+E18+E21+E25+E28+E32+E37 -> 0 | F38: =F11+F15+F18+F21+F25+F28+F32+F37 -> 0 | G38: =G11+G15+G18+G21+G25+G28+G32+G37 -> 0 | H38: =H11+H15+H18+H21+H25+H28+H32+H37 -> 0 | I38: =I11+I15+I18+I21+I25+I28+I32+I37 -> 0
B40: Filling rules: (1) Enter amounts in INR Lakhs with two decimals in the cream cells only. (2) Leave blank or enter 0 where not applicable – it will display as '-'. (3) For every non-zero figure, write the schedule/page of the audited accounts in 'Audit Reference'. (4) Light-navy and navy cells are formulas – do not overwrite. (5) Refer to Sheet 2 (G3/G4) for include/exclude rules.

Sheet 4. Revenue Expenditure
B2: SHEET 4 – REVENUE EXPENDITURE (INR LAKHS)
B3: Record the REVENUE (recurring) expenditure incurred in each financial year on salaries, maintenance, administration, scholarships & assistance, electricity, transport, career guidance & skilling, employee benefits, extracurricular and co-curricular activities etc. Source: Income & Expenditure Account and expenditure schedules (audited). EXCLUDE depreciation, provisions and any item capitalised or already reported in Metric 4.1 (including rentals).
B5: Code | C5: Head / Sub-head (INR Lakhs) | D5: FY 2025-26 | E5: FY 2024-25 | F5: FY 2023-24 | G5: FY 2022-23 | H5: NAAC 3-Yr Total (FY 23-24 to 25-26) | I5: 4-Yr Total (FY 22-23 to 25-26) | J5: Audit Reference (Schedule / Page) | K5: Remarks
B6: 1 | C6: Salaries
B7: 1.1 | C7: Teaching staff salaries (incl. visiting / contract faculty) | H7: =SUM(D7:F7) -> 0 | I7: =SUM(D7:G7) -> 0
B8: 1.2 | C8: Non-teaching staff salaries & wages | H8: =SUM(D8:F8) -> 0 | I8: =SUM(D8:G8) -> 0
C9: Sub-total 1 – Salaries | D9: =SUM(D7:D8) -> 0 | E9: =SUM(E7:E8) -> 0 | F9: =SUM(F7:F8) -> 0 | G9: =SUM(G7:G8) -> 0 | H9: =SUM(H7:H8) -> 0 | I9: =SUM(I7:I8) -> 0
B10: 2 | C10: Maintenance
B11: 2.1 | C11: Repairs & maintenance – buildings & campus | H11: =SUM(D11:F11) -> 0 | I11: =SUM(D11:G11) -> 0
B12: 2.2 | C12: Repairs & maintenance – labs, equipment & IT (incl. AMC) | H12: =SUM(D12:F12) -> 0 | I12: =SUM(D12:G12) -> 0
B13: 2.3 | C13: Housekeeping, security & gardening | H13: =SUM(D13:F13) -> 0 | I13: =SUM(D13:G13) -> 0
C14: Sub-total 2 – Maintenance | D14: =SUM(D11:D13) -> 0 | E14: =SUM(E11:E13) -> 0 | F14: =SUM(F11:F13) -> 0 | G14: =SUM(G11:G13) -> 0 | H14: =SUM(H11:H13) -> 0 | I14: =SUM(I11:I13) -> 0
B15: 3 | C15: Administration
B16: 3.1 | C16: Office & communication expenses (printing, stationery, telephone, internet) | H16: =SUM(D16:F16) -> 0 | I16: =SUM(D16:G16) -> 0
B17: 3.2 | C17: Legal, professional, audit & accreditation / ranking fees | H17: =SUM(D17:F17) -> 0 | I17: =SUM(D17:G17) -> 0
B18: 3.3 | C18: Advertisement, publicity & insurance of assets | H18: =SUM(D18:F18) -> 0 | I18: =SUM(D18:G18) -> 0
C19: Sub-total 3 – Administration | D19: =SUM(D16:D18) -> 0 | E19: =SUM(E16:E18) -> 0 | F19: =SUM(F16:F18) -> 0 | G19: =SUM(G16:G18) -> 0 | H19: =SUM(H16:H18) -> 0 | I19: =SUM(I16:I18) -> 0
B20: 4 | C20: Scholarships & Assistance
B21: 4.1 | C21: Fee waivers / freeships from institutional funds | H21: =SUM(D21:F21) -> 0 | I21: =SUM(D21:G21) -> 0
B22: 4.2 | C22: Merit / need-based scholarships & financial assistance | H22: =SUM(D22:F22) -> 0 | I22: =SUM(D22:G22) -> 0
C23: Sub-total 4 – Scholarships & Assistance | D23: =SUM(D21:D22) -> 0 | E23: =SUM(E21:E22) -> 0 | F23: =SUM(F21:F22) -> 0 | G23: =SUM(G21:G22) -> 0 | H23: =SUM(H21:H22) -> 0 | I23: =SUM(I21:I22) -> 0
B24: 5 | C24: Electricity & Utilities
B25: 5.1 | C25: Electricity, water & fuel charges | H25: =SUM(D25:F25) -> 0 | I25: =SUM(D25:G25) -> 0
C26: Sub-total 5 – Electricity & Utilities | D26: =SUM(D25:D25) -> 0 | E26: =SUM(E25:E25) -> 0 | F26: =SUM(F25:F25) -> 0 | G26: =SUM(G25:G25) -> 0 | H26: =SUM(H25:H25) -> 0 | I26: =SUM(I25:I25) -> 0
B27: 6 | C27: Transport
B28: 6.1 | C28: Transport operating expenses (hire, fuel, maintenance) | H28: =SUM(D28:F28) -> 0 | I28: =SUM(D28:G28) -> 0
C29: Sub-total 6 – Transport | D29: =SUM(D28:D28) -> 0 | E29: =SUM(E28:E28) -> 0 | F29: =SUM(F28:F28) -> 0 | G29: =SUM(G28:G28) -> 0 | H29: =SUM(H28:H28) -> 0 | I29: =SUM(I28:I28) -> 0
B30: 7 | C30: Career Guidance & Skilling
B31: 7.1 | C31: Training & placement / career guidance expenses | H31: =SUM(D31:F31) -> 0 | I31: =SUM(D31:G31) -> 0
B32: 7.2 | C32: Skilling, certification & value-added programmes | H32: =SUM(D32:F32) -> 0 | I32: =SUM(D32:G32) -> 0
C33: Sub-total 7 – Career Guidance & Skilling | D33: =SUM(D31:D32) -> 0 | E33: =SUM(E31:E32) -> 0 | F33: =SUM(F31:F32) -> 0 | G33: =SUM(G31:G32) -> 0 | H33: =SUM(H31:H32) -> 0 | I33: =SUM(I31:I32) -> 0
B34: 8 | C34: Employee Benefits
B35: 8.1 | C35: Employer PF / ESI / gratuity / leave encashment | H35: =SUM(D35:F35) -> 0 | I35: =SUM(D35:G35) -> 0
B36: 8.2 | C36: Group insurance, staff welfare & FDP sponsorship | H36: =SUM(D36:F36) -> 0 | I36: =SUM(D36:G36) -> 0
C37: Sub-total 8 – Employee Benefits | D37: =SUM(D35:D36) -> 0 | E37: =SUM(E35:E36) -> 0 | F37: =SUM(F35:F36) -> 0 | G37: =SUM(G35:G36) -> 0 | H37: =SUM(H35:H36) -> 0 | I37: =SUM(I35:I36) -> 0
B38: 9 | C38: Extracurricular & Co-curricular Activities
B39: 9.1 | C39: Cultural, sports & technical events / clubs | H39: =SUM(D39:F39) -> 0 | I39: =SUM(D39:G39) -> 0
B40: 9.2 | C40: NSS / NCC, outreach, wellbeing & value-education activities | H40: =SUM(D40:F40) -> 0 | I40: =SUM(D40:G40) -> 0
C41: Sub-total 9 – Extracurricular & Co-curricular Activities | D41: =SUM(D39:D40) -> 0 | E41: =SUM(E39:E40) -> 0 | F41: =SUM(F39:F40) -> 0 | G41: =SUM(G39:G40) -> 0 | H41: =SUM(H39:H40) -> 0 | I41: =SUM(I39:I40) -> 0
B42: 10 | C42: Other Revenue Expenditure (specify in Remarks)
...

Sheet 5. Summary & Ratio
B2: SHEET 5 – SUMMARY, NAAC DATA TEMPLATE & RATIO ANALYSIS
B3: This sheet is fully formula-driven. Values flow from Sheets 3 and 4 – do not type here, except in Section E (reconciliation inputs). Section A gives the figures to be entered on the NAAC portal (FY 2023-24 to 2025-26). FY 2022-23 is shown for trend/reference only.
B5: A. NAAC DATA TEMPLATE (INR LAKHS)
B6: # | C6: Item | D6: FY 2025-26 (Year-3) | E6: FY 2024-25 (Year-2) | F6: FY 2023-24 (Year-1) | G6: FY 2022-23 (Baseline) | H6: NAAC 3-Yr Total | I6: 4-Yr Total
B7: 1 | C7: Total amount earned through Fees, R&D grants, Salary Grants, Alumni contribution, Consultancy, Endowments, Scholarships | D7: ='3. Revenue Income'!D38 -> 0 | E7: ='3. Revenue Income'!E38 -> 0 | F7: ='3. Revenue Income'!F38 -> 0 | G7: ='3. Revenue Income'!G38 -> 0 | H7: ='3. Revenue Income'!H38 -> 0 | I7: ='3. Revenue Income'!I38 -> 0
B8: 2 | C8: Total amount spent towards salaries, maintenance, administration, scholarships & assistance, electricity, transport, career guidance and skilling, employee benefits, extracurricular and co-curricular activities etc. | D8: ='4. Revenue Expenditure'!D49 -> 0 | E8: ='4. Revenue Expenditure'!E49 -> 0 | F8: ='4. Revenue Expenditure'!F49 -> 0 | G8: ='4. Revenue Expenditure'!G49 -> 0 | H8: ='4. Revenue Expenditure'!H49 -> 0 | I8: ='4. Revenue Expenditure'!I49 -> 0
B10: B. RATIO ANALYSIS
B11: # | C11: Indicator | D11: FY 2025-26 | E11: FY 2024-25 | F11: FY 2023-24 | G11: FY 2022-23 | H11: NAAC 3-Yr Aggregate | I11: 4-Yr Aggregate
B12: 3 | C12: Revenue Coverage Ratio (Income ÷ Expenditure) – KEY INDICATOR | D12: =IF(D8=0,"-",D7/D8) -> - | E12: =IF(E8=0,"-",E7/E8) -> - | F12: =IF(F8=0,"-",F7/F8) -> - | G12: =IF(G8=0,"-",G7/G8) -> - | H12: =IF(H8=0,"-",H7/H8) -> - | I12: =IF(I8=0,"-",I7/I8) -> -
B13: 4 | C13: Operating Surplus / (Deficit) (Income – Expenditure), INR Lakhs | D13: =D7-D8 -> 0 | E13: =E7-E8 -> 0 | F13: =F7-F8 -> 0 | G13: =G7-G8 -> 0 | H13: =H7-H8 -> 0 | I13: =I7-I8 -> 0
B14: 5 | C14: Surplus Margin % (Surplus ÷ Income) | D14: =IF(D7=0,"-",D13/D7) -> - | E14: =IF(E7=0,"-",E13/E7) -> - | F14: =IF(F7=0,"-",F13/F7) -> - | G14: =IF(G7=0,"-",G13/G7) -> - | H14: =IF(H7=0,"-",H13/H7) -> - | I14: =IF(I7=0,"-",I13/I7) -> -
B15: 6 | C15: Fee Dependency % (Fees ÷ Income) | D15: =IF(D7=0,"-",'3. Revenue Income'!D11/D7) -> - | E15: =IF(E7=0,"-",'3. Revenue Income'!E11/E7) -> - | F15: =IF(F7=0,"-",'3. Revenue Income'!F11/F7) -> - | G15: =IF(G7=0,"-",'3. Revenue Income'!G11/G7) -> - | H15: =IF(H7=0,"-",'3. Revenue Income'!H11/H7) -> - | I15: =IF(I7=0,"-",'3. Revenue Income'!I11/I7) -> -
B16: 7 | C16: Salary & Benefits Share % ((Salaries + Benefits) ÷ Expenditure) | D16: =IF(D8=0,"-",('4. Revenue Expenditure'!D9+'4. Revenue Expenditure'!D37)/D8) -> - | E16: =IF(E8=0,"-",('4. Revenue Expenditure'!E9+'4. Revenue Expenditure'!E37)/E8) -> - | F16: =IF(F8=0,"-",('4. Revenue Expenditure'!F9+'4. Revenue Expenditure'!F37)/F8) -> - | G16: =IF(G8=0,"-",('4. Revenue Expenditure'!G9+'4. Revenue Expenditure'!G37)/G8) -> - | H16: =IF(H8=0,"-",('4. Revenue Expenditure'!H9+'4. Revenue Expenditure'!H37)/H8) -> - | I16: =IF(I8=0,"-",('4. Revenue Expenditure'!I9+'4. Revenue Expenditure'!I37)/I8) -> -
B17: 8 | C17: Year-on-Year Growth – Revenue Income | D17: =IF(OR(E7=0,D7=0),"-",D7/E7-1) -> - | E17: =IF(OR(F7=0,E7=0),"-",E7/F7-1) -> - | F17: =IF(OR(G7=0,F7=0),"-",F7/G7-1) -> - | G17: n.a. | H17: n.a. | I17: n.a.
B18: 9 | C18: Year-on-Year Growth – Revenue Expenditure | D18: =IF(OR(E8=0,D8=0),"-",D8/E8-1) -> - | E18: =IF(OR(F8=0,E8=0),"-",E8/F8-1) -> - | F18: =IF(OR(G8=0,F8=0),"-",F8/G8-1) -> - | G18: n.a. | H18: n.a. | I18: n.a.
B19: 10 | C19: Interpretation (indicative band – see Sheet 2, G6) | D19: =IF(D7=0,"Enter data",IF(D12<0.95,"Band I – Operating deficit",IF(D12<1,"Band II – Marginal / break-even",IF(D12<=1.25,"Band III – Healthy / self-sustaining","Band IV – High surplus (show reinvestment)")))) -> Enter data | E19: =IF(E7=0,"Enter data",IF(E12<0.95,"Band I – Operating deficit",IF(E12<1,"Band II – Marginal / break-even",IF(E12<=1.25,"Band III – Healthy / self-sustaining","Band IV – High surplus (show reinvestment)")))) -> Enter data | F19: =IF(F7=0,"Enter data",IF(F12<0.95,"Band I – Operating deficit",IF(F12<1,"Band II – Marginal / break-even",IF(F12<=1.25,"Band III – Healthy / self-sustaining","Band IV – High surplus (show reinvestment)")))) -> Enter data | G19: =IF(G7=0,"Enter data",IF(G12<0.95,"Band I – Operating deficit",IF(G12<1,"Band II – Marginal / break-even",IF(G12<=1.25,"Band III – Healthy / self-sustaining","Band IV – High surplus (show reinvestment)")))) -> Enter data | H19: =IF(H7=0,"Enter data",IF(H12<0.95,"Band I – Operating deficit",IF(H12<1,"Band II – Marginal / break-even",IF(H12<=1.25,"Band III – Healthy / self-sustaining","Band IV – High surplus (show reinvestment)")))) -> Enter data | I19: =IF(I7=0,"Enter data",IF(I12<0.95,"Band I – Operating deficit",IF(I12<1,"Band II – Marginal / break-even",IF(I12<=1.25,"Band III – Healthy / self-sustaining","Band IV – High surplus (show reinvestment)")))) -> Enter data
B21: C. COMPOSITION – SHARE OF EACH HEAD (NAAC 3-YEAR PERIOD)
B22: Code | C22: Revenue Income Head | D22: NAAC 3-Yr (INR Lakhs) | E22: Share %
B23: A | C23: Fees | D23: ='3. Revenue Income'!H11 -> 0 | E23: =IF($H$7=0,"-",D23/$H$7) -> -
B24: B | C24: R&D Grants | D24: ='3. Revenue Income'!H15 -> 0 | E24: =IF($H$7=0,"-",D24/$H$7) -> -
B25: C | C25: Salary Grants | D25: ='3. Revenue Income'!H18 -> 0 | E25: =IF($H$7=0,"-",D25/$H$7) -> -
B26: D | C26: Alumni Contribution | D26: ='3. Revenue Income'!H21 -> 0 | E26: =IF($H$7=0,"-",D26/$H$7) -> -
B27: E | C27: Consultancy & Training | D27: ='3. Revenue Income'!H25 -> 0 | E27: =IF($H$7=0,"-",D27/$H$7) -> -
B28: F | C28: Endowment Income | D28: ='3. Revenue Income'!H28 -> 0 | E28: =IF($H$7=0,"-",D28/$H$7) -> -
B29: G | C29: Scholarships Received | D29: ='3. Revenue Income'!H32 -> 0 | E29: =IF($H$7=0,"-",D29/$H$7) -> -
B30: H | C30: Other Revenue Income (specify in Remarks) | D30: ='3. Revenue Income'!H37 -> 0 | E30: =IF($H$7=0,"-",D30/$H$7) -> -
B32: Code | C32: Revenue Expenditure Head | D32: NAAC 3-Yr (INR Lakhs) | E32: Share %
B33: 1 | C33: Salaries | D33: ='4. Revenue Expenditure'!H9 -> 0 | E33: =IF($H$8=0,"-",D33/$H$8) -> -
B34: 2 | C34: Maintenance | D34: ='4. Revenue Expenditure'!H14 -> 0 | E34: =IF($H$8=0,"-",D34/$H$8) -> -
B35: 3 | C35: Administration | D35: ='4. Revenue Expenditure'!H19 -> 0 | E35: =IF($H$8=0,"-",D35/$H$8) -> -
B36: 4 | C36: Scholarships & Assistance | D36: ='4. Revenue Expenditure'!H23 -> 0 | E36: =IF($H$8=0,"-",D36/$H$8) -> -
B37: 5 | C37: Electricity & Utilities | D37: ='4. Revenue Expenditure'!H26 -> 0 | E37: =IF($H$8=0,"-",D37/$H$8) -> -
B38: 6 | C38: Transport | D38: ='4. Revenue Expenditure'!H29 -> 0 | E38: =IF($H$8=0,"-",D38/$H$8) -> -
B39: 7 | C39: Career Guidance & Skilling | D39: ='4. Revenue Expenditure'!H33 -> 0 | E39: =IF($H$8=0,"-",D39/$H$8) -> -
B40: 8 | C40: Employee Benefits | D40: ='4. Revenue Expenditure'!H37 -> 0 | E40: =IF($H$8=0,"-",D40/$H$8) -> -
B41: 9 | C41: Extracurricular & Co-curricular Activities | D41: ='4. Revenue Expenditure'!H41 -> 0 | E41: =IF($H$8=0,"-",D41/$H$8) -> -
B42: 10 | C42: Other Revenue Expenditure (specify in Remarks) | D42: ='4. Revenue Expenditure'!H48 -> 0 | E42: =IF($H$8=0,"-",D42/$H$8) -> -
B44: D. LINKAGE WITH METRIC 3.2 (EXPENDITURE EXCLUDING SALARY)
B45: # | C45: Item | D45: FY 2025-26 | E45: FY 2024-25 | F45: FY 2023-24 | G45: FY 2022-23 | H45: NAAC 3-Yr | I45: 4-Yr
B46: D1 | C46: Revenue expenditure excluding Salaries & Employee benefits (INR Lakhs) | D46: =D8-'4. Revenue Expenditure'!D9-'4. Revenue Expenditure'!D37 -> 0 | E46: =E8-'4. Revenue Expenditure'!E9-'4. Revenue Expenditure'!E37 -> 0 | F46: =F8-'4. Revenue Expenditure'!F9-'4. Revenue Expenditure'!F37 -> 0 | G46: =G8-'4. Revenue Expenditure'!G9-'4. Revenue Expenditure'!G37 -> 0 | H46: =H8-'4. Revenue Expenditure'!H9-'4. Revenue Expenditure'!H37 -> 0 | I46: =I8-'4. Revenue Expenditure'!I9-'4. Revenue Expenditure'!I37 -> 0
...

Sheet 6. Worked Example
B2: SHEET 6 – WORKED EXAMPLE (HYPOTHETICAL FIGURES – FOR UNDERSTANDING ONLY)
B3: The figures below are purely illustrative and do NOT represent any institution's accounts. They show how category totals translate into the NAAC template, the ratio and its interpretation.
B5: Step 1 – Revenue Income by category (INR Lakhs)
B6: Code | C6: Head | D6: FY 2025-26 | E6: FY 2024-25 | F6: FY 2023-24 | G6: FY 2022-23 | H6: NAAC 3-Yr | I6: 4-Yr
B7: A | C7: Fees | D7: 9500 | E7: 8800 | F7: 7600 | G7: 6800 | H7: =SUM(D7:F7) -> 25900 | I7: =SUM(D7:G7) -> 32700
B8: B | C8: R&D grants | D8: 250 | E8: 200 | F8: 150 | G8: 120 | H8: =SUM(D8:F8) -> 600 | I8: =SUM(D8:G8) -> 720
B9: C | C9: Salary grants | D9: 0 | E9: 0 | F9: 0 | G9: 0 | H9: =SUM(D9:F9) -> 0 | I9: =SUM(D9:G9) -> 0
B10: D | C10: Alumni contribution | D10: 20 | E10: 15 | F10: 10 | G10: 10 | H10: =SUM(D10:F10) -> 45 | I10: =SUM(D10:G10) -> 55
B11: E | C11: Consultancy & training | D11: 80 | E11: 60 | F11: 50 | G11: 40 | H11: =SUM(D11:F11) -> 190 | I11: =SUM(D11:G11) -> 230
B12: F | C12: Endowment income | D12: 30 | E12: 25 | F12: 20 | G12: 20 | H12: =SUM(D12:F12) -> 75 | I12: =SUM(D12:G12) -> 95
B13: G | C13: Scholarships received | D13: 600 | E13: 550 | F13: 500 | G13: 450 | H13: =SUM(D13:F13) -> 1650 | I13: =SUM(D13:G13) -> 2100
B14: H | C14: Other revenue income | D14: 220 | E14: 180 | F14: 150 | G14: 120 | H14: =SUM(D14:F14) -> 550 | I14: =SUM(D14:G14) -> 670
C15: Total Revenue Income | D15: =SUM(D7:D14) -> 10700 | E15: =SUM(E7:E14) -> 9830 | F15: =SUM(F7:F14) -> 8480 | G15: =SUM(G7:G14) -> 7560 | H15: =SUM(H7:H14) -> 29010 | I15: =SUM(I7:I14) -> 36570
B17: Step 2 – Revenue Expenditure by category (INR Lakhs)
B18: Code | C18: Head | D18: FY 2025-26 | E18: FY 2024-25 | F18: FY 2023-24 | G18: FY 2022-23 | H18: NAAC 3-Yr | I18: 4-Yr
B19: 1 | C19: Salaries | D19: 5200 | E19: 4800 | F19: 4400 | G19: 4000 | H19: =SUM(D19:F19) -> 14400 | I19: =SUM(D19:G19) -> 18400
B20: 2 | C20: Maintenance | D20: 700 | E20: 650 | F20: 600 | G20: 550 | H20: =SUM(D20:F20) -> 1950 | I20: =SUM(D20:G20) -> 2500
B21: 3 | C21: Administration | D21: 650 | E21: 600 | F21: 560 | G21: 520 | H21: =SUM(D21:F21) -> 1810 | I21: =SUM(D21:G21) -> 2330
B22: 4 | C22: Scholarships & assistance | D22: 500 | E22: 450 | F22: 400 | G22: 380 | H22: =SUM(D22:F22) -> 1350 | I22: =SUM(D22:G22) -> 1730
B23: 5 | C23: Electricity & utilities | D23: 300 | E23: 280 | F23: 260 | G23: 240 | H23: =SUM(D23:F23) -> 840 | I23: =SUM(D23:G23) -> 1080
B24: 6 | C24: Transport | D24: 250 | E24: 230 | F24: 210 | G24: 200 | H24: =SUM(D24:F24) -> 690 | I24: =SUM(D24:G24) -> 890
B25: 7 | C25: Career guidance & skilling | D25: 120 | E25: 100 | F25: 90 | G25: 80 | H25: =SUM(D25:F25) -> 310 | I25: =SUM(D25:G25) -> 390
B26: 8 | C26: Employee benefits | D26: 600 | E26: 550 | F26: 500 | G26: 450 | H26: =SUM(D26:F26) -> 1650 | I26: =SUM(D26:G26) -> 2100
B27: 9 | C27: Extracurricular & co-curricular | D27: 180 | E27: 160 | F27: 140 | G27: 120 | H27: =SUM(D27:F27) -> 480 | I27: =SUM(D27:G27) -> 600
B28: 10 | C28: Other revenue expenditure | D28: 200 | E28: 180 | F28: 170 | G28: 150 | H28: =SUM(D28:F28) -> 550 | I28: =SUM(D28:G28) -> 700
C29: Total Revenue Expenditure | D29: =SUM(D19:D28) -> 8700 | E29: =SUM(E19:E28) -> 8000 | F29: =SUM(F19:F28) -> 7330 | G29: =SUM(G19:G28) -> 6690 | H29: =SUM(H19:H28) -> 24030 | I29: =SUM(I19:I28) -> 30720
B31: Step 3 – Ratio and interpretation
B32: # | C32: Indicator | D32: FY 2025-26 | E32: FY 2024-25 | F32: FY 2023-24 | G32: FY 2022-23 | H32: NAAC 3-Yr | I32: 4-Yr
B33: a | C33: Revenue Coverage Ratio (Income ÷ Expenditure) | D33: =IF(D29=0,"-",D15/D29) -> 1.2298851 | E33: =IF(E29=0,"-",E15/E29) -> 1.22875 | F33: =IF(F29=0,"-",F15/F29) -> 1.1568895 | G33: =IF(G29=0,"-",G15/G29) -> 1.1300448 | H33: =IF(H29=0,"-",H15/H29) -> 1.2072409 | I33: =IF(I29=0,"-",I15/I29) -> 1.1904297
B34: b | C34: Operating Surplus / (Deficit), INR Lakhs | D34: =D15-D29 -> 2000 | E34: =E15-E29 -> 1830 | F34: =F15-F29 -> 1150 | G34: =G15-G29 -> 870 | H34: =H15-H29 -> 4980 | I34: =I15-I29 -> 5850
B35: c | C35: Surplus Margin % | D35: =IF(D15=0,"-",D34/D15) -> 0.18691589 | E35: =IF(E15=0,"-",E34/E15) -> 0.1861648 | F35: =IF(F15=0,"-",F34/F15) -> 0.13561321 | G35: =IF(G15=0,"-",G34/G15) -> 0.11507937 | H35: =IF(H15=0,"-",H34/H15) -> 0.17166494 | I35: =IF(I15=0,"-",I34/I15) -> 0.15996719
B36: d | C36: Fee Dependency % | D36: =IF(D15=0,"-",D7/D15) -> 0.88785047 | E36: =IF(E15=0,"-",E7/E15) -> 0.89521872 | F36: =IF(F15=0,"-",F7/F15) -> 0.89622642 | G36: =IF(G15=0,"-",G7/G15) -> 0.8994709 | H36: =IF(H15=0,"-",H7/H15) -> 0.89279559 | I36: =IF(I15=0,"-",I7/I15) -> 0.89417555
B37: e | C37: Salary & Benefits Share % | D37: =IF(D29=0,"-",(D19+D26)/D29) -> 0.66666667 | E37: =IF(E29=0,"-",(E19+E26)/E29) -> 0.66875 | F37: =IF(F29=0,"-",(F19+F26)/F29) -> 0.66848568 | G37: =IF(G29=0,"-",(G19+G26)/G29) -> 0.6651719 | H37: =IF(H29=0,"-",(H19+H26)/H29) -> 0.66791511 | I37: =IF(I29=0,"-",(I19+I26)/I29) -> 0.66731771
B38: f | C38: Interpretation band | D38: =IF(D15=0,"-",IF(D33<0.95,"Band I – Deficit",IF(D33<1,"Band II – Marginal",IF(D33<=1.25,"Band III – Healthy","Band IV – High surplus")))) -> Band III – Healthy | E38: =IF(E15=0,"-",IF(E33<0.95,"Band I – Deficit",IF(E33<1,"Band II – Marginal",IF(E33<=1.25,"Band III – Healthy","Band IV – High surplus")))) -> Band III – Healthy | F38: =IF(F15=0,"-",IF(F33<0.95,"Band I – Deficit",IF(F33<1,"Band II – Marginal",IF(F33<=1.25,"Band III – Healthy","Band IV – High surplus")))) -> Band III – Healthy | G38: =IF(G15=0,"-",IF(G33<0.95,"Band I – Deficit",IF(G33<1,"Band II – Marginal",IF(G33<=1.25,"Band III – Healthy","Band IV – High surplus")))) -> Band III – Healthy | H38: =IF(H15=0,"-",IF(H33<0.95,"Band I – Deficit",IF(H33<1,"Band II – Marginal",IF(H33<=1.25,"Band III – Healthy","Band IV – High surplus")))) -> Band III – Healthy | I38: =IF(I15=0,"-",IF(I33<0.95,"Band I – Deficit",IF(I33<1,"Band II – Marginal",IF(I33<=1.25,"Band III – Healthy","Band IV – High surplus")))) -> Band III – Healthy
B40: How to read this example
B41: 1. In FY 2025-26 the institution earned 10,700 Lakhs and spent 8,700 Lakhs on running costs – a Revenue Coverage Ratio of about 1.23x (Band III – healthy). The operating surplus of 2,000 Lakhs (about 18.7% of income) is available for reinvestment. 2. Over the NAAC three-year period (FY 2023-24 to 2025-26) the institution earned 29,010 Lakhs against expenditure of 24,030 Lakhs – an aggregate ratio of about 1.21x, showing consistent self-sufficiency. 3. Fees form about 89% of income – typical for a self-financed university. Growing consultancy, training, R&D and alumni income will reduce fee dependency and strengthen the case under Metric 4.3 (diversification). 4. Salaries plus employee benefits are about 67% of revenue expenditure – a normal level for a teaching-intensive institution. 5. The surplus should be visibly reinvested – e.g., in capital expenditure reported in Metric 4.1 and corpus creation in Metric 4.3. Mention this linkage in the explanatory note. 6. For the actual submission, enter real figures in Sheets 3 and 4; Sheet 5 will produce these indicators automatically.

Sheet 7. Document Checklist
B2: SHEET 7 – SUPPORTING DOCUMENT CHECKLIST
B3: Select the status for each document and financial year from the drop-down (Available / Pending / Not Applicable). Items 1 and 2 are mandatory as per NAAC; the rest are recommended evidence for Data Validation & Verification (DVV).
B5: # | C5: Document | D5: Purpose / What to highlight | E5: FY 2025-26 | F5: FY 2024-25 | G5: FY 2023-24 | H5: FY 2022-23 | I5: Responsibility | J5: File name / Link / Remarks
B6: 1 | C6: Audited Income & Expenditure statement – signed by CA & countersigned by competent authority (MANDATORY) | D6: Highlight revenue income and revenue expenditure components | E6: Pending | F6: Pending | G6: Pending | H6: Pending | I6: Finance Officer
B7: 2 | C7: CA-certified audit extract of revenue income and revenue expenditure (MANDATORY – Sheet 8 format) | D7: Must match Sheet 5 Section A exactly | E7: Pending | F7: Pending | G7: Pending | H7: Pending | I7: CA / Finance Officer
B8: 3 | C8: Income schedules of the audited accounts | D8: Fees, grants, consultancy, endowment and other income | E8: Pending | F8: Pending | G8: Pending | H8: Pending | I8: Finance Office
B9: 4 | C9: Expenditure schedules of the audited accounts | D9: Salaries, maintenance, administration and other heads | E9: Pending | F9: Pending | G9: Pending | H9: Pending | I9: Finance Office
B10: 5 | C10: Reconciliation statement (Sheet 5, Section E) | D10: Workbook totals vs audited I&E; depreciation and exclusions | E10: Pending | F10: Pending | G10: Pending | H10: Pending | I10: Finance Office
B11: 6 | C11: Fee collection register summary | D11: Fees by programme / category | E11: Pending | F11: Pending | G11: Pending | H11: Pending | I11: Accounts – Fee Section
B12: 7 | C12: Salary register summary & statutory returns (PF / ESI) | D12: Salaries and employee benefits | E12: Pending | F12: Pending | G12: Pending | H12: Pending | I12: HR / Accounts
B13: 8 | C13: R&D grant and consultancy / training ledgers | D13: Must match Metrics 9.1 and 9.7 | E13: Pending | F13: Pending | G13: Pending | H13: Pending | I13: Research Office / Accounts
B14: 9 | C14: Scholarship & freeship disbursement records | D14: Scholarships received and given | E14: Pending | F14: Pending | G14: Pending | H14: Pending | I14: Scholarship Cell / Accounts
B15: 10 | C15: Endowment fund statement | D15: Income earned on endowments | E15: Pending | F15: Pending | G15: Pending | H15: Pending | I15: Finance Office
B16: 11 | C16: Explanatory note for years with ratio outside 1.00x–1.25x | D16: Reason for deficit / use of surplus | E16: Pending | F16: Pending | G16: Pending | H16: Pending | I16: IQAC & Finance Officer
C17: Documents Available (count) | E17: =COUNTIF(E6:E16,"Available")&" / "&(11-COUNTIF(E6:E16,"Not Applicable")) -> 0 / 11 | F17: =COUNTIF(F6:F16,"Available")&" / "&(11-COUNTIF(F6:F16,"Not Applicable")) -> 0 / 11 | G17: =COUNTIF(G6:G16,"Available")&" / "&(11-COUNTIF(G6:G16,"Not Applicable")) -> 0 / 11 | H17: =COUNTIF(H6:H16,"Available")&" / "&(11-COUNTIF(H6:H16,"Not Applicable")) -> 0 / 11

Sheet 8. CA Certificate
B2: CERTIFICATE BY CHARTERED ACCOUNTANT
B3: (To be printed on the letterhead of the Chartered Accountant firm)
B5: Ref. No.: ____________________ Date: ____________________
B6: Sub.: Certificate of Revenue Income and Revenue Expenditure of [University Name] for NAAC Metric 4.2 (Binary Accreditation Framework) – Financial Years 2022-23 to 2025-26
B8: This is to certify that we have verified the audited Income & Expenditure Accounts and related schedules of [University Name] for the financial years mentioned below. Based on our verification, the total revenue income earned through fees, R&D grants, salary grants, alumni contribution, consultancy, endowments, scholarships etc., and the total revenue expenditure on salaries, maintenance, administration, scholarships & assistance, electricity, transport, career guidance and skilling, employee benefits, extracurricular and co-curricular activities etc., are as under:
B10: S. No. | C10: Financial Year | D10: Revenue Income (INR Lakhs) | E10: Revenue Expenditure (INR Lakhs) | F10: Revenue Coverage Ratio
B11: 1 | C11: FY 2025-26 | D11: ='5. Summary & Ratio'!D7 -> 0 | E11: ='5. Summary & Ratio'!D8 -> 0 | F11: =IF(E11=0,"-",D11/E11) -> -
B12: 2 | C12: FY 2024-25 | D12: ='5. Summary & Ratio'!E7 -> 0 | E12: ='5. Summary & Ratio'!E8 -> 0 | F12: =IF(E12=0,"-",D12/E12) -> -
B13: 3 | C13: FY 2023-24 | D13: ='5. Summary & Ratio'!F7 -> 0 | E13: ='5. Summary & Ratio'!F8 -> 0 | F13: =IF(E13=0,"-",D13/E13) -> -
B14: 4 | C14: FY 2022-23 | D14: ='5. Summary & Ratio'!G7 -> 0 | E14: ='5. Summary & Ratio'!G8 -> 0 | F14: =IF(E14=0,"-",D14/E14) -> -
C15: Total – NAAC period (FY 2023-24 to 2025-26) | D15: =SUM(D11:D13) -> 0 | E15: =SUM(E11:E13) -> 0 | F15: =IF(E15=0,"-",D15/E15) -> -
B17: We further certify that (i) revenue income excludes capital receipts such as loans, capital grants and contributions for infrastructure; (ii) revenue expenditure excludes depreciation, provisions, capitalised items and rentals reported under Metric 4.1; (iii) the figures reconcile with the audited Income & Expenditure Accounts after the exclusions stated above; and (iv) the relevant components have been highlighted in the audited statements enclosed herewith.
B20: For ____________________ (CA Firm Name) | E20: Countersigned by
B21: Chartered Accountants, FRN: __________ | E21: Registrar / Finance Officer
E22: [University Name]
B23: (Signature & Seal) | E23: (Signature & Seal)
B24: Name of Partner: ____________________
B25: Membership No.: __________ UDIN: __________
B27: Place: [City] Enclosures: Highlighted audited statements for FY 2022-23, 2023-24, 2024-25 and 2025-26
