Workbook

Sheet 1. Cover
B2: [UNIVERSITY NAME]
B3: Internal Quality Assurance Cell (IQAC)
B5: NAAC Binary Accreditation Framework | Attribute 4 – Financial Resources & Management (50)
B6: Metric 4.1 – Ratio of Capital Income vs Capital Expenditure (Weightage: 15)
B7: Data Capture, Computation & Evidence Workbook • Financial Years 2025-26, 2024-25, 2023-24 and 2022-23 • All amounts in INR Lakhs
B9: ABSTRACT
B10: This workbook is the institutional tool for preparing NAAC Metric 4.1 – Ratio of Capital Income vs Capital Expenditure. It captures, head-wise, every capital receipt (government capital grants, management/sponsoring-body contributions, loans disbursed and endowments) and every capital expenditure (instructional buildings, academic infrastructure including library, hostels, laboratories and equipment, residences, amenities and payment of rentals) for four financial years – 2025-26, 2024-25, 2023-24 and 2022-23. All totals, ratios and interpretations are calculated automatically by formula. The Summary sheet reproduces the figures in the exact NAAC data-template format for the three-year assessment period (FY 2023-24 to 2025-26), while FY 2022-23 is retained as a baseline/reference year for trend analysis and in case the notified assessment window differs. Guidelines, a fully worked example, an evidence checklist and a Chartered Accountant (CA) certificate format are included so that the Finance Office and IQAC can submit data that is complete, consistent and fully traceable to audited accounts.
B12: INTRODUCTION
B13: Why this metric matters: NAAC uses Metric 4.1 to judge whether an institution mobilises long-term (capital) funds and actually converts them into physical and academic infrastructure. A healthy relationship between capital income and capital expenditure shows sound financial planning, timely utilisation of grants and contributions, and continuous investment in the learning environment. What is compared: • Capital Income – money received specifically for creating long-term assets (not operating revenue). • Capital Expenditure – money spent on creating or enhancing long-term assets, plus payment of rentals for academic premises (explicitly included by NAAC). How it is presented: For each financial year, NAAC asks for (1) the total amount received towards capital and (2) the total amount spent on infrastructure, both in INR Lakhs, supported by audited statements certified by a CA and countersigned by the competent authority. Link with other metrics: Metric 4.1 deals only with capital items. Operating income and expenditure (fees, salaries, maintenance, electricity, etc.) belong to Metric 4.2. Figures used here must also reconcile with Metric 3.2 (Learning Resources), which uses total expenditure excluding salary.
B15: OBJECTIVES OF THIS WORKBOOK
B16: 1. Provide a single, standard format in which the Finance Office records capital income and expenditure head-wise for four financial years. 2. Compute the Capital Utilisation Ratio, Capital Coverage Ratio, capital surplus/deficit and year-on-year growth automatically. 3. Generate the NAAC data-template values for the assessment period without manual re-typing. 4. Link every figure to its source in the audited accounts (schedule / page reference) for verification. 5. Track availability of every supporting document required by NAAC.
B18: WORKBOOK STRUCTURE
B19: Sheet | C19: Purpose | D19: Who fills / uses | E19: Action required
B20: 1. Cover | C20: Abstract, introduction, objectives and structure of the workbook | D20: All users | E20: Read first
B21: 2. Guidelines | C21: Definitions, include/exclude rules, step-by-step procedure, formulas, interpretation bands, documents and common errors | D21: Finance Office & IQAC | E21: Read before entering data
B22: 3. Capital Income | C22: Head-wise capital receipts for each FY with audit reference | D22: Finance Office | E22: Enter figures in cream cells
B23: 4. Capital Expenditure | C23: Head-wise capital spending for each FY with audit reference | D23: Finance Office | E23: Enter figures in cream cells
B24: 5. Summary & Ratio | C24: NAAC data template, ratios, interpretation, composition and chart | D24: IQAC (auto-calculated) | E24: Review only – no entry
B25: 6. Worked Example | C25: Illustration with hypothetical figures explaining how to read the results | D25: Training / reference | E25: Read only
B26: 7. Document Checklist | C26: Status of every supporting document, FY-wise | D26: IQAC & Finance Office | E26: Select status from drop-down
B27: 8. CA Certificate | C27: Certificate format pre-filled from the Summary, for CA signature | D27: CA / Finance Officer | E27: Print, verify and sign
B29: CELL COLOUR LEGEND
B30: Cream fill, blue text | C30: Input cell – enter data here (INR Lakhs, two decimals)
B31: Light navy fill, black text | C31: Formula / subtotal – do not overwrite
B32: Green text | C32: Value linked from another sheet – do not overwrite
B33: Navy fill, gold/white text | C33: Headings and sections
B35: Prepared by: IQAC, [University Name] | Version 1.0 | Basis: NAAC Binary Accreditation Framework – Metrics for Manual (Base), Draft Version
B36: Note: The NAAC draft names the ratio but does not publish a scoring formula or bands. Interpretation bands in this workbook are indicative IQAC guidance; update them when NAAC notifies the final SOP.

Sheet 2. Guidelines
B2: GUIDELINES FOR PREPARING METRIC 4.1
B3: G1. ASSESSMENT PERIOD AND YEAR BASIS
B4: • Use FINANCIAL YEARS (1 April – 31 March), not academic years. • NAAC assessment period = last three completed financial years: FY 2025-26 (Year-3, latest), FY 2024-25 (Year-2) and FY 2023-24 (Year-1). • FY 2022-23 is captured as a baseline year for trend analysis and as a reserve in case the notified assessment window is different. It is NOT included in the NAAC three-year totals. • All amounts in INR Lakhs, rounded to two decimals (₹1,00,000 = 1.00 Lakh).
B6: G2. STEP-BY-STEP PROCEDURE
B7: Step | C7: Activity | D7: How to do it | E7: Responsibility / Output
B8: 1 | C8: Collect audited accounts | D8: Obtain audited Balance Sheet, Income & Expenditure Account, Receipts & Payments Account and all schedules for each of the four FYs | E8: Finance Office – signed audited statements
B9: 2 | C9: Identify capital receipts | D9: From the Balance Sheet (capital fund, corpus, earmarked funds, secured loans) and Receipts & Payments, list amounts actually RECEIVED during each FY | E9: Finance Office – working list
B10: 3 | C10: Classify income | D10: Map each receipt to one head in Sheet 3 using the include/exclude rules in G3 | E10: Finance Office
B11: 4 | C11: Identify capital expenditure | D11: From the Fixed Asset Schedule take ADDITIONS during the year (including Capital Work-in-Progress) and add rent paid for leased academic premises | E11: Finance Office – working list
B12: 5 | C12: Classify expenditure | D12: Map each item to one head in Sheet 4 using G4. Count every rupee only once | E12: Finance Office
B13: 6 | C13: Enter data | D13: Type figures in cream input cells only; write the schedule/page reference of the audited accounts in the 'Audit Reference' column | E13: Finance Office
B14: 7 | C14: Review results | D14: Check Sheet 5 – totals, ratios, interpretation and the reconciliation checks | E14: IQAC Director
B15: 8 | C15: Obtain CA certificate | D15: Print Sheet 8, have the statutory/internal CA verify against audited accounts and sign; countersign by Registrar / Finance Officer | E15: CA & competent authority
B16: 9 | C16: Highlight evidence | D16: Highlight the relevant lines in the audited statements for each FY and scan them | E16: Finance Office
B17: 10 | C17: Upload | D17: Enter the three-year values from Sheet 5 (Section A) on the NAAC portal and upload the CA certificate and highlighted audited statements | E17: IQAC
B19: G3. CAPITAL INCOME – WHAT TO INCLUDE AND EXCLUDE
B20: Code | C20: Head | D20: Include | E20: Exclude / Where to look
B21: A | C21: Government grants (capital / non-recurring) | D21: Grants from UGC, MoE, RUSA, State Government, DST-FIST, AICTE schemes etc. sanctioned for buildings, equipment or infrastructure – amount actually released in the FY | E21: Exclude salary grants and recurring grants (go to 4.2). Source: grant ledger, sanction letters, Utilisation Certificates
B22: B | C22: Management / sponsoring-body contributions | D22: Funds infused by the Trust / Society / sponsoring body for capital purposes; corpus transferred for infrastructure | E22: Exclude contributions meant to meet operating deficits. Source: capital fund schedule, Trust resolutions, bank statements
B23: C | C23: Loans (disbursed) | D23: Term loans from banks, HEFA or financial institutions actually DISBURSED in the FY for infrastructure | E23: Exclude sanctioned-but-undisbursed amounts, overdraft/working-capital limits, loan repayments. Source: secured-loan schedule, disbursement advice
B24: D | C24: Endowments & donations (capital) | D24: Endowments, capital donations, alumni contributions and CSR funds received for buildings, labs, equipment | E24: Exclude endowments whose interest funds scholarships or prizes (revenue). Source: endowment schedule, donation receipts, CSR agreements
B25: E | C25: Any other capital receipts | D25: Any other receipt explicitly earmarked for capital assets – specify in Remarks | E25: Exclude fee income, consultancy, R&D project overheads
B27: G4. CAPITAL EXPENDITURE – WHAT TO INCLUDE AND EXCLUDE
B28: Code | C28: Head | D28: Include | E28: Exclude / Where to look
B29: 1 | C29: Instructional buildings | D29: New academic blocks, extensions, classrooms, building CWIP additions | E29: Exclude repairs, painting, maintenance (revenue). Source: fixed asset schedule – buildings & CWIP
B30: 2 | C30: Academic infrastructure incl. library | D30: Library building/furniture, capitalised books & e-resources, smart classrooms, academic furniture | E30: Exclude annual subscriptions treated as revenue in accounts. Source: fixed asset schedule – library, furniture
B31: 3 | C31: Hostels | D31: Construction, extension and furnishing of hostels | E31: Exclude hostel running cost, mess expenses
B32: 4 | C32: Laboratories & equipment | D32: Lab equipment, computers, servers, networking, research instruments, software capitalised | E32: Exclude consumables, AMC, calibration charges
B33: 5 | C33: Residences | D33: Staff quarters, guest house (if residential) | E33: Exclude repairs and upkeep
B34: 6 | C34: Amenities | D34: Sports facilities, auditorium, canteen, solar plant, STP/RWH, CCTV, vehicles, lifts/ramps | E34: Exclude electricity bills, fuel, routine maintenance
B35: 7 | C35: Payment of rentals | D35: Rent paid for leased academic/hostel premises (NAAC explicitly includes this) | E35: Exclude rent for non-academic purposes; avoid double counting with 4.2
B36: 8 | C36: Any other capital expenditure | D36: Other assets capitalised in accounts – specify in Remarks | E36: Exclude anything not capitalised in audited accounts (except rentals)
B38: G5. FORMULAS USED IN THIS WORKBOOK
B39: # | C39: Indicator | D39: Formula | E39: Meaning
B40: 1 | C40: Total Capital Income | D40: A + B + C + D + E | E40: Total amount received towards capital in the FY
B41: 2 | C41: Total Capital Expenditure | D41: 1 + 2 + 3 + 4 + 5 + 6 + 7 + 8 | E41: Total amount spent towards infrastructure in the FY
B42: 3 | C42: Capital Utilisation Ratio | D42: Total Capital Expenditure ÷ Total Capital Income | E42: Rupees spent on infrastructure for every rupee of capital received (key indicator)
B43: 4 | C43: Capital Coverage Ratio | D43: Total Capital Income ÷ Total Capital Expenditure | E43: Extent to which infrastructure spending is funded by capital sources
B44: 5 | C44: Capital Surplus / (Deficit) | D44: Total Capital Income – Total Capital Expenditure | E44: Positive = unspent capital; negative = capex funded from revenue surplus
B45: 6 | C45: Year-on-Year Growth | D45: (Current FY ÷ Previous FY) – 1 | E45: Trend in capital mobilisation and investment
...

Sheet 3. Capital Income
B2: SHEET 3 – CAPITAL INCOME (INR LAKHS)
B3: Record the amount RECEIVED towards capital in each financial year – Government grants, management contributions, loans, endowments etc. Use only amounts actually credited during the FY (not sanctioned amounts). Source: Balance Sheet schedules (Capital Fund, Corpus, Earmarked Funds, Secured Loans), Receipts & Payments Account, grant and loan ledgers.
B5: Code | C5: Head / Sub-head (INR Lakhs) | D5: FY 2025-26 | E5: FY 2024-25 | F5: FY 2023-24 | G5: FY 2022-23 | H5: NAAC 3-Yr Total (FY 23-24 to 25-26) | I5: 4-Yr Total (FY 22-23 to 25-26) | J5: Audit Reference (Schedule / Page) | K5: Remarks
B6: A | C6: Government Grants (Capital / Non-recurring)
B7: A1 | C7: UGC / Ministry of Education / Central Government capital grants | H7: =SUM(D7:F7) -> 0 | I7: =SUM(D7:G7) -> 0
B8: A2 | C8: State Government capital grants | H8: =SUM(D8:F8) -> 0 | I8: =SUM(D8:G8) -> 0
B9: A3 | C9: RUSA / PM-USHA / other scheme grants for infrastructure | H9: =SUM(D9:F9) -> 0 | I9: =SUM(D9:G9) -> 0
B10: A4 | C10: DST-FIST / AICTE / other agency grants for equipment & labs | H10: =SUM(D10:F10) -> 0 | I10: =SUM(D10:G10) -> 0
C11: Sub-total A – Government Grants (Capital / Non-recurring) | D11: =SUM(D7:D10) -> 0 | E11: =SUM(E7:E10) -> 0 | F11: =SUM(F7:F10) -> 0 | G11: =SUM(G7:G10) -> 0 | H11: =SUM(H7:H10) -> 0 | I11: =SUM(I7:I10) -> 0
B12: B | C12: Management / Sponsoring-Body Contributions
B13: B1 | C13: Trust / Society contribution for infrastructure | H13: =SUM(D13:F13) -> 0 | I13: =SUM(D13:G13) -> 0
B14: B2 | C14: Corpus / reserves transferred for capital purposes | H14: =SUM(D14:F14) -> 0 | I14: =SUM(D14:G14) -> 0
C15: Sub-total B – Management / Sponsoring-Body Contributions | D15: =SUM(D13:D14) -> 0 | E15: =SUM(E13:E14) -> 0 | F15: =SUM(F13:F14) -> 0 | G15: =SUM(G13:G14) -> 0 | H15: =SUM(H13:H14) -> 0 | I15: =SUM(I13:I14) -> 0
B16: C | C16: Loans (Amount Disbursed in the FY)
B17: C1 | C17: Term loans from banks / financial institutions | H17: =SUM(D17:F17) -> 0 | I17: =SUM(D17:G17) -> 0
B18: C2 | C18: HEFA / other institutional loans | H18: =SUM(D18:F18) -> 0 | I18: =SUM(D18:G18) -> 0
C19: Sub-total C – Loans (Amount Disbursed in the FY) | D19: =SUM(D17:D18) -> 0 | E19: =SUM(E17:E18) -> 0 | F19: =SUM(F17:F18) -> 0 | G19: =SUM(G17:G18) -> 0 | H19: =SUM(H17:H18) -> 0 | I19: =SUM(I17:I18) -> 0
B20: D | C20: Endowments, Donations & CSR (Capital)
B21: D1 | C21: Endowments received for capital purposes | H21: =SUM(D21:F21) -> 0 | I21: =SUM(D21:G21) -> 0
B22: D2 | C22: Capital donations / alumni contributions | H22: =SUM(D22:F22) -> 0 | I22: =SUM(D22:G22) -> 0
B23: D3 | C23: CSR funds received for infrastructure | H23: =SUM(D23:F23) -> 0 | I23: =SUM(D23:G23) -> 0
C24: Sub-total D – Endowments, Donations & CSR (Capital) | D24: =SUM(D21:D23) -> 0 | E24: =SUM(E21:E23) -> 0 | F24: =SUM(F21:F23) -> 0 | G24: =SUM(G21:G23) -> 0 | H24: =SUM(H21:H23) -> 0 | I24: =SUM(I21:I23) -> 0
B25: E | C25: Any Other Capital Receipts (specify in Remarks)
B26: E1 | C26: Other capital receipt – 1 | H26: =SUM(D26:F26) -> 0 | I26: =SUM(D26:G26) -> 0
B27: E2 | C27: Other capital receipt – 2 | H27: =SUM(D27:F27) -> 0 | I27: =SUM(D27:G27) -> 0
C28: Sub-total E – Any Other Capital Receipts (specify in Remarks) | D28: =SUM(D26:D27) -> 0 | E28: =SUM(E26:E27) -> 0 | F28: =SUM(F26:F27) -> 0 | G28: =SUM(G26:G27) -> 0 | H28: =SUM(H26:H27) -> 0 | I28: =SUM(I26:I27) -> 0
B29: TOTAL | C29: Total amount received towards Capital – Government grants, management contributions, loans, endowments etc. | D29: =D11+D15+D19+D24+D28 -> 0 | E29: =E11+E15+E19+E24+E28 -> 0 | F29: =F11+F15+F19+F24+F28 -> 0 | G29: =G11+G15+G19+G24+G28 -> 0 | H29: =H11+H15+H19+H24+H28 -> 0 | I29: =I11+I15+I19+I24+I28 -> 0
B31: Filling rules: (1) Enter amounts in INR Lakhs with two decimals in the cream cells only. (2) Leave a cell blank or enter 0 where not applicable – it will display as '-'. (3) For every non-zero figure, write the schedule/page of the audited accounts in 'Audit Reference'. (4) Grey/navy cells are formulas – do not overwrite. (5) Refer to Sheet 2 (G3/G4) for include/exclude rules.

Sheet 4. Capital Expenditure
B2: SHEET 4 – CAPITAL EXPENDITURE (INR LAKHS)
B3: Record the amount SPENT on infrastructure in each financial year – instructional buildings, academic infrastructure including library, hostels, laboratories, equipment, residences, amenities and payment of rentals. Source: Fixed Asset Schedule ('Additions during the year' and Capital Work-in-Progress) and lease/rent ledger. Do NOT include repairs, maintenance or consumables.
B5: Code | C5: Head / Sub-head (INR Lakhs) | D5: FY 2025-26 | E5: FY 2024-25 | F5: FY 2023-24 | G5: FY 2022-23 | H5: NAAC 3-Yr Total (FY 23-24 to 25-26) | I5: 4-Yr Total (FY 22-23 to 25-26) | J5: Audit Reference (Schedule / Page) | K5: Remarks
B6: 1 | C6: Instructional Buildings
B7: 1.1 | C7: New academic buildings / blocks (incl. CWIP additions) | H7: =SUM(D7:F7) -> 0 | I7: =SUM(D7:G7) -> 0
B8: 1.2 | C8: Extensions / additional classrooms | H8: =SUM(D8:F8) -> 0 | I8: =SUM(D8:G8) -> 0
C9: Sub-total 1 – Instructional Buildings | D9: =SUM(D7:D8) -> 0 | E9: =SUM(E7:E8) -> 0 | F9: =SUM(F7:F8) -> 0 | G9: =SUM(G7:G8) -> 0 | H9: =SUM(H7:H8) -> 0 | I9: =SUM(I7:I8) -> 0
B10: 2 | C10: Academic Infrastructure including Library
B11: 2.1 | C11: Library building, furniture & fixtures | H11: =SUM(D11:F11) -> 0 | I11: =SUM(D11:G11) -> 0
B12: 2.2 | C12: Books, journals & e-resources (capitalised) | H12: =SUM(D12:F12) -> 0 | I12: =SUM(D12:G12) -> 0
B13: 2.3 | C13: Smart classrooms / ICT-enabled classrooms | H13: =SUM(D13:F13) -> 0 | I13: =SUM(D13:G13) -> 0
B14: 2.4 | C14: Academic furniture & fixtures | H14: =SUM(D14:F14) -> 0 | I14: =SUM(D14:G14) -> 0
C15: Sub-total 2 – Academic Infrastructure including Library | D15: =SUM(D11:D14) -> 0 | E15: =SUM(E11:E14) -> 0 | F15: =SUM(F11:F14) -> 0 | G15: =SUM(G11:G14) -> 0 | H15: =SUM(H11:H14) -> 0 | I15: =SUM(I11:I14) -> 0
B16: 3 | C16: Hostels
B17: 3.1 | C17: Hostel construction / extension (incl. CWIP) | H17: =SUM(D17:F17) -> 0 | I17: =SUM(D17:G17) -> 0
B18: 3.2 | C18: Hostel furniture & fittings | H18: =SUM(D18:F18) -> 0 | I18: =SUM(D18:G18) -> 0
C19: Sub-total 3 – Hostels | D19: =SUM(D17:D18) -> 0 | E19: =SUM(E17:E18) -> 0 | F19: =SUM(F17:F18) -> 0 | G19: =SUM(G17:G18) -> 0 | H19: =SUM(H17:H18) -> 0 | I19: =SUM(I17:I18) -> 0
B20: 4 | C20: Laboratories & Equipment
B21: 4.1 | C21: Laboratory equipment & instruments | H21: =SUM(D21:F21) -> 0 | I21: =SUM(D21:G21) -> 0
B22: 4.2 | C22: Computers, servers, networking & IT hardware | H22: =SUM(D22:F22) -> 0 | I22: =SUM(D22:G22) -> 0
B23: 4.3 | C23: Software (capitalised) | H23: =SUM(D23:F23) -> 0 | I23: =SUM(D23:G23) -> 0
B24: 4.4 | C24: Research / central instrumentation equipment | H24: =SUM(D24:F24) -> 0 | I24: =SUM(D24:G24) -> 0
C25: Sub-total 4 – Laboratories & Equipment | D25: =SUM(D21:D24) -> 0 | E25: =SUM(E21:E24) -> 0 | F25: =SUM(F21:F24) -> 0 | G25: =SUM(G21:G24) -> 0 | H25: =SUM(H21:H24) -> 0 | I25: =SUM(I21:I24) -> 0
B26: 5 | C26: Residences
B27: 5.1 | C27: Staff quarters / residences | H27: =SUM(D27:F27) -> 0 | I27: =SUM(D27:G27) -> 0
C28: Sub-total 5 – Residences | D28: =SUM(D27:D27) -> 0 | E28: =SUM(E27:E27) -> 0 | F28: =SUM(F27:F27) -> 0 | G28: =SUM(G27:G27) -> 0 | H28: =SUM(H27:H27) -> 0 | I28: =SUM(I27:I27) -> 0
B29: 6 | C29: Amenities
B30: 6.1 | C30: Sports facilities, gymnasium & grounds | H30: =SUM(D30:F30) -> 0 | I30: =SUM(D30:G30) -> 0
B31: 6.2 | C31: Auditorium, seminar halls, canteen | H31: =SUM(D31:F31) -> 0 | I31: =SUM(D31:G31) -> 0
B32: 6.3 | C32: Solar plant, STP, rainwater harvesting & green infrastructure | H32: =SUM(D32:F32) -> 0 | I32: =SUM(D32:G32) -> 0
B33: 6.4 | C33: Vehicles, CCTV, lifts, ramps & other amenities | H33: =SUM(D33:F33) -> 0 | I33: =SUM(D33:G33) -> 0
C34: Sub-total 6 – Amenities | D34: =SUM(D30:D33) -> 0 | E34: =SUM(E30:E33) -> 0 | F34: =SUM(F30:F33) -> 0 | G34: =SUM(G30:G33) -> 0 | H34: =SUM(H30:H33) -> 0 | I34: =SUM(I30:I33) -> 0
B35: 7 | C35: Payment of Rentals
B36: 7.1 | C36: Rent for leased academic / hostel premises | H36: =SUM(D36:F36) -> 0 | I36: =SUM(D36:G36) -> 0
C37: Sub-total 7 – Payment of Rentals | D37: =SUM(D36:D36) -> 0 | E37: =SUM(E36:E36) -> 0 | F37: =SUM(F36:F36) -> 0 | G37: =SUM(G36:G36) -> 0 | H37: =SUM(H36:H36) -> 0 | I37: =SUM(I36:I36) -> 0
B38: 8 | C38: Any Other Capital Expenditure (specify in Remarks)
B39: 8.1 | C39: Other capital expenditure – 1 | H39: =SUM(D39:F39) -> 0 | I39: =SUM(D39:G39) -> 0
C40: Sub-total 8 – Any Other Capital Expenditure (specify in Remarks) | D40: =SUM(D39:D39) -> 0 | E40: =SUM(E39:E39) -> 0 | F40: =SUM(F39:F39) -> 0 | G40: =SUM(G39:G39) -> 0 | H40: =SUM(H39:H39) -> 0 | I40: =SUM(I39:I39) -> 0
B41: TOTAL | C41: Total amount spent towards infrastructure like instructional building, academic infrastructure incl. library, hostels, laboratory, equipment, residences, amenities, payment of rentals | D41: =D9+D15+D19+D25+D28+D34+D37+D40 -> 0 | E41: =E9+E15+E19+E25+E28+E34+E37+E40 -> 0 | F41: =F9+F15+F19+F25+F28+F34+F37+F40 -> 0 | G41: =G9+G15+G19+G25+G28+G34+G37+G40 -> 0 | H41: =H9+H15+H19+H25+H28+H34+H37+H40 -> 0 | I41: =I9+I15+I19+I25+I28+I34+I37+I40 -> 0
B43: Filling rules: (1) Enter amounts in INR Lakhs with two decimals in the cream cells only. (2) Leave a cell blank or enter 0 where not applicable – it will display as '-'. (3) For every non-zero figure, write the schedule/page of the audited accounts in 'Audit Reference'. (4) Grey/navy cells are formulas – do not overwrite. (5) Refer to Sheet 2 (G3/G4) for include/exclude rules.

Sheet 5. Summary & Ratio
B2: SHEET 5 – SUMMARY, NAAC DATA TEMPLATE & RATIO ANALYSIS
B3: This sheet is fully formula-driven. Values flow from Sheets 3 and 4 – do not type here. Section A gives the figures to be entered on the NAAC portal (assessment period FY 2023-24 to 2025-26). FY 2022-23 is shown for trend/reference only.
B5: A. NAAC DATA TEMPLATE (INR LAKHS)
B6: # | C6: Item | D6: FY 2025-26 (Year-3) | E6: FY 2024-25 (Year-2) | F6: FY 2023-24 (Year-1) | G6: FY 2022-23 (Baseline) | H6: NAAC 3-Yr Total | I6: 4-Yr Total
B7: 1 | C7: Total amount received towards Capital – Government grants, management contributions, loans, endowments etc. | D7: ='3. Capital Income'!D29 -> 0 | E7: ='3. Capital Income'!E29 -> 0 | F7: ='3. Capital Income'!F29 -> 0 | G7: ='3. Capital Income'!G29 -> 0 | H7: ='3. Capital Income'!H29 -> 0 | I7: ='3. Capital Income'!I29 -> 0
B8: 2 | C8: Total amount spent towards infrastructure like instructional building, academic infrastructure including library, hostels, laboratory, equipment, residences, amenities, payment of rentals | D8: ='4. Capital Expenditure'!D41 -> 0 | E8: ='4. Capital Expenditure'!E41 -> 0 | F8: ='4. Capital Expenditure'!F41 -> 0 | G8: ='4. Capital Expenditure'!G41 -> 0 | H8: ='4. Capital Expenditure'!H41 -> 0 | I8: ='4. Capital Expenditure'!I41 -> 0
B10: B. RATIO ANALYSIS
B11: # | C11: Indicator | D11: FY 2025-26 | E11: FY 2024-25 | F11: FY 2023-24 | G11: FY 2022-23 | H11: NAAC 3-Yr Aggregate | I11: 4-Yr Aggregate
B12: 3 | C12: Capital Utilisation Ratio (CapEx ÷ CapInc) – KEY INDICATOR | D12: =IF(D7=0,"-",D8/D7) -> - | E12: =IF(E7=0,"-",E8/E7) -> - | F12: =IF(F7=0,"-",F8/F7) -> - | G12: =IF(G7=0,"-",G8/G7) -> - | H12: =IF(H7=0,"-",H8/H7) -> - | I12: =IF(I7=0,"-",I8/I7) -> -
B13: 4 | C13: Capital Coverage Ratio (CapInc ÷ CapEx) | D13: =IF(D8=0,"-",D7/D8) -> - | E13: =IF(E8=0,"-",E7/E8) -> - | F13: =IF(F8=0,"-",F7/F8) -> - | G13: =IF(G8=0,"-",G7/G8) -> - | H13: =IF(H8=0,"-",H7/H8) -> - | I13: =IF(I8=0,"-",I7/I8) -> -
B14: 5 | C14: Capital Surplus / (Deficit) (CapInc – CapEx), INR Lakhs | D14: =D7-D8 -> 0 | E14: =E7-E8 -> 0 | F14: =F7-F8 -> 0 | G14: =G7-G8 -> 0 | H14: =H7-H8 -> 0 | I14: =I7-I8 -> 0
B15: 6 | C15: Year-on-Year Growth – Capital Income | D15: =IF(OR(E7=0,D7=0),"-",D7/E7-1) -> - | E15: =IF(OR(F7=0,E7=0),"-",E7/F7-1) -> - | F15: =IF(OR(G7=0,F7=0),"-",F7/G7-1) -> - | G15: n.a. | H15: n.a. | I15: n.a.
B16: 7 | C16: Year-on-Year Growth – Capital Expenditure | D16: =IF(OR(E8=0,D8=0),"-",D8/E8-1) -> - | E16: =IF(OR(F8=0,E8=0),"-",E8/F8-1) -> - | F16: =IF(OR(G8=0,F8=0),"-",F8/G8-1) -> - | G16: n.a. | H16: n.a. | I16: n.a.
B17: 8 | C17: Interpretation (indicative band – see Sheet 2, G6) | D17: =IF(D7=0,"Enter data",IF(D12<0.5,"Band I – Low utilisation",IF(D12<0.8,"Band II – Moderate",IF(D12<=1.2,"Band III – Balanced / Optimal","Band IV – CapEx exceeds capital receipts")))) -> Enter data | E17: =IF(E7=0,"Enter data",IF(E12<0.5,"Band I – Low utilisation",IF(E12<0.8,"Band II – Moderate",IF(E12<=1.2,"Band III – Balanced / Optimal","Band IV – CapEx exceeds capital receipts")))) -> Enter data | F17: =IF(F7=0,"Enter data",IF(F12<0.5,"Band I – Low utilisation",IF(F12<0.8,"Band II – Moderate",IF(F12<=1.2,"Band III – Balanced / Optimal","Band IV – CapEx exceeds capital receipts")))) -> Enter data | G17: =IF(G7=0,"Enter data",IF(G12<0.5,"Band I – Low utilisation",IF(G12<0.8,"Band II – Moderate",IF(G12<=1.2,"Band III – Balanced / Optimal","Band IV – CapEx exceeds capital receipts")))) -> Enter data | H17: =IF(H7=0,"Enter data",IF(H12<0.5,"Band I – Low utilisation",IF(H12<0.8,"Band II – Moderate",IF(H12<=1.2,"Band III – Balanced / Optimal","Band IV – CapEx exceeds capital receipts")))) -> Enter data | I17: =IF(I7=0,"Enter data",IF(I12<0.5,"Band I – Low utilisation",IF(I12<0.8,"Band II – Moderate",IF(I12<=1.2,"Band III – Balanced / Optimal","Band IV – CapEx exceeds capital receipts")))) -> Enter data
B19: C. COMPOSITION – SHARE OF EACH HEAD (NAAC 3-YEAR PERIOD)
B20: Code | C20: Capital Income Head | D20: NAAC 3-Yr (INR Lakhs) | E20: Share %
B21: A | C21: Government Grants (Capital / Non-recurring) | D21: ='3. Capital Income'!H11 -> 0 | E21: =IF($H$7=0,"-",D21/$H$7) -> -
B22: B | C22: Management / Sponsoring-Body Contributions | D22: ='3. Capital Income'!H15 -> 0 | E22: =IF($H$7=0,"-",D22/$H$7) -> -
B23: C | C23: Loans (Amount Disbursed in the FY) | D23: ='3. Capital Income'!H19 -> 0 | E23: =IF($H$7=0,"-",D23/$H$7) -> -
B24: D | C24: Endowments, Donations & CSR (Capital) | D24: ='3. Capital Income'!H24 -> 0 | E24: =IF($H$7=0,"-",D24/$H$7) -> -
B25: E | C25: Any Other Capital Receipts (specify in Remarks) | D25: ='3. Capital Income'!H28 -> 0 | E25: =IF($H$7=0,"-",D25/$H$7) -> -
B27: Code | C27: Capital Expenditure Head | D27: NAAC 3-Yr (INR Lakhs) | E27: Share %
B28: 1 | C28: Instructional Buildings | D28: ='4. Capital Expenditure'!H9 -> 0 | E28: =IF($H$8=0,"-",D28/$H$8) -> -
B29: 2 | C29: Academic Infrastructure including Library | D29: ='4. Capital Expenditure'!H15 -> 0 | E29: =IF($H$8=0,"-",D29/$H$8) -> -
B30: 3 | C30: Hostels | D30: ='4. Capital Expenditure'!H19 -> 0 | E30: =IF($H$8=0,"-",D30/$H$8) -> -
B31: 4 | C31: Laboratories & Equipment | D31: ='4. Capital Expenditure'!H25 -> 0 | E31: =IF($H$8=0,"-",D31/$H$8) -> -
B32: 5 | C32: Residences | D32: ='4. Capital Expenditure'!H28 -> 0 | E32: =IF($H$8=0,"-",D32/$H$8) -> -
B33: 6 | C33: Amenities | D33: ='4. Capital Expenditure'!H34 -> 0 | E33: =IF($H$8=0,"-",D33/$H$8) -> -
B34: 7 | C34: Payment of Rentals | D34: ='4. Capital Expenditure'!H37 -> 0 | E34: =IF($H$8=0,"-",D34/$H$8) -> -
B35: 8 | C35: Any Other Capital Expenditure (specify in Remarks) | D35: ='4. Capital Expenditure'!H40 -> 0 | E35: =IF($H$8=0,"-",D35/$H$8) -> -
B37: D. CHART – CAPITAL INCOME vs CAPITAL EXPENDITURE
B62: Reading the results: A Capital Utilisation Ratio close to 1.00x (0.80x–1.20x) is the strongest position – it shows that capital funds raised were deployed into infrastructure. Where the ratio is far from 1, prepare a short explanatory note (e.g., unspent grant awaiting tender, or capex funded from accumulated revenue surplus) to accompany the submission.

Sheet 6. Worked Example
B2: SHEET 6 – WORKED EXAMPLE (HYPOTHETICAL FIGURES – FOR UNDERSTANDING ONLY)
B3: The figures below are purely illustrative and do NOT represent any institution's accounts. They show how category totals translate into the NAAC template, the ratio and its interpretation.
B5: Step 1 – Capital Income by category (INR Lakhs)
B6: Code | C6: Head | D6: FY 2025-26 | E6: FY 2024-25 | F6: FY 2023-24 | G6: FY 2022-23 | H6: NAAC 3-Yr | I6: 4-Yr
B7: A | C7: Government grants (capital) | D7: 150 | E7: 120 | F7: 80 | G7: 60 | H7: =SUM(D7:F7) -> 350 | I7: =SUM(D7:G7) -> 410
B8: B | C8: Management / sponsoring-body contributions | D8: 900 | E8: 800 | F8: 700 | G8: 600 | H8: =SUM(D8:F8) -> 2400 | I8: =SUM(D8:G8) -> 3000
B9: C | C9: Loans disbursed | D9: 500 | E9: 450 | F9: 300 | G9: 250 | H9: =SUM(D9:F9) -> 1250 | I9: =SUM(D9:G9) -> 1500
B10: D | C10: Endowments, donations & CSR | D10: 60 | E10: 40 | F10: 35 | G10: 30 | H10: =SUM(D10:F10) -> 135 | I10: =SUM(D10:G10) -> 165
B11: E | C11: Other capital receipts | D11: 0 | E11: 10 | F11: 5 | G11: 0 | H11: =SUM(D11:F11) -> 15 | I11: =SUM(D11:G11) -> 15
C12: Total Capital Income | D12: =SUM(D7:D11) -> 1610 | E12: =SUM(E7:E11) -> 1420 | F12: =SUM(F7:F11) -> 1120 | G12: =SUM(G7:G11) -> 940 | H12: =SUM(H7:H11) -> 4150 | I12: =SUM(I7:I11) -> 5090
B14: Step 2 – Capital Expenditure by category (INR Lakhs)
B15: Code | C15: Head | D15: FY 2025-26 | E15: FY 2024-25 | F15: FY 2023-24 | G15: FY 2022-23 | H15: NAAC 3-Yr | I15: 4-Yr
B16: 1 | C16: Instructional buildings | D16: 600 | E16: 700 | F16: 380 | G16: 300 | H16: =SUM(D16:F16) -> 1680 | I16: =SUM(D16:G16) -> 1980
B17: 2 | C17: Academic infrastructure incl. library | D17: 140 | E17: 120 | F17: 100 | G17: 80 | H17: =SUM(D17:F17) -> 360 | I17: =SUM(D17:G17) -> 440
B18: 3 | C18: Hostels | D18: 300 | E18: 250 | F18: 200 | G18: 150 | H18: =SUM(D18:F18) -> 750 | I18: =SUM(D18:G18) -> 900
B19: 4 | C19: Laboratories & equipment | D19: 350 | E19: 280 | F19: 220 | G19: 190 | H19: =SUM(D19:F19) -> 850 | I19: =SUM(D19:G19) -> 1040
B20: 5 | C20: Residences | D20: 0 | E20: 40 | F20: 20 | G20: 0 | H20: =SUM(D20:F20) -> 60 | I20: =SUM(D20:G20) -> 60
B21: 6 | C21: Amenities | D21: 120 | E21: 100 | F21: 90 | G21: 70 | H21: =SUM(D21:F21) -> 310 | I21: =SUM(D21:G21) -> 380
B22: 7 | C22: Payment of rentals | D22: 45 | E22: 40 | F22: 35 | G22: 30 | H22: =SUM(D22:F22) -> 120 | I22: =SUM(D22:G22) -> 150
B23: 8 | C23: Other capital expenditure | D23: 5 | E23: 0 | F23: 0 | G23: 10 | H23: =SUM(D23:F23) -> 5 | I23: =SUM(D23:G23) -> 15
C24: Total Capital Expenditure | D24: =SUM(D16:D23) -> 1560 | E24: =SUM(E16:E23) -> 1530 | F24: =SUM(F16:F23) -> 1045 | G24: =SUM(G16:G23) -> 830 | H24: =SUM(H16:H23) -> 4135 | I24: =SUM(I16:I23) -> 4965
B26: Step 3 – Ratio and interpretation
B27: # | C27: Indicator | D27: FY 2025-26 | E27: FY 2024-25 | F27: FY 2023-24 | G27: FY 2022-23 | H27: NAAC 3-Yr | I27: 4-Yr
B28: a | C28: Capital Utilisation Ratio (CapEx ÷ CapInc) | D28: =IF(D12=0,"-",D24/D12) -> 0.9689441 | E28: =IF(E12=0,"-",E24/E12) -> 1.0774648 | F28: =IF(F12=0,"-",F24/F12) -> 0.93303571 | G28: =IF(G12=0,"-",G24/G12) -> 0.88297872 | H28: =IF(H12=0,"-",H24/H12) -> 0.99638554 | I28: =IF(I12=0,"-",I24/I12) -> 0.97544204
B29: b | C29: Capital Surplus / (Deficit), INR Lakhs | D29: =D12-D24 -> 50 | E29: =E12-E24 -> -110 | F29: =F12-F24 -> 75 | G29: =G12-G24 -> 110 | H29: =H12-H24 -> 15 | I29: =I12-I24 -> 125
B30: c | C30: Interpretation band | D30: =IF(D12=0,"-",IF(D28<0.5,"Band I – Low",IF(D28<0.8,"Band II – Moderate",IF(D28<=1.2,"Band III – Balanced","Band IV – Exceeds receipts")))) -> Band III – Balanced | E30: =IF(E12=0,"-",IF(E28<0.5,"Band I – Low",IF(E28<0.8,"Band II – Moderate",IF(E28<=1.2,"Band III – Balanced","Band IV – Exceeds receipts")))) -> Band III – Balanced | F30: =IF(F12=0,"-",IF(F28<0.5,"Band I – Low",IF(F28<0.8,"Band II – Moderate",IF(F28<=1.2,"Band III – Balanced","Band IV – Exceeds receipts")))) -> Band III – Balanced | G30: =IF(G12=0,"-",IF(G28<0.5,"Band I – Low",IF(G28<0.8,"Band II – Moderate",IF(G28<=1.2,"Band III – Balanced","Band IV – Exceeds receipts")))) -> Band III – Balanced | H30: =IF(H12=0,"-",IF(H28<0.5,"Band I – Low",IF(H28<0.8,"Band II – Moderate",IF(H28<=1.2,"Band III – Balanced","Band IV – Exceeds receipts")))) -> Band III – Balanced | I30: =IF(I12=0,"-",IF(I28<0.5,"Band I – Low",IF(I28<0.8,"Band II – Moderate",IF(I28<=1.2,"Band III – Balanced","Band IV – Exceeds receipts")))) -> Band III – Balanced
B32: How to read this example
B33: 1. In FY 2025-26 the institution received 1,610 Lakhs of capital and spent 1,560 Lakhs – a ratio of about 0.97x (Band III). Almost every rupee raised was converted into assets. 2. In FY 2024-25 spending (1,530) was higher than receipts (1,420) – ratio about 1.08x, still balanced. The small deficit was met from revenue surplus; mention this in the explanatory note. 3. Over the NAAC three-year period (FY 2023-24 to 2025-26), the aggregate ratio is about 1.00x, which demonstrates disciplined capital planning. 4. Management contributions (Head B) are the dominant capital source – typical for a private university. Government grants are small but should still be shown with sanction letters. 5. For the actual submission, enter real figures in Sheets 3 and 4; Sheet 5 will produce these same indicators automatically.

Sheet 7. Document Checklist
B2: SHEET 7 – SUPPORTING DOCUMENT CHECKLIST
B3: Select the status for each document and financial year from the drop-down (Available / Pending / Not Applicable). Items 1 and 2 are mandatory as per NAAC; the rest are recommended evidence for Data Validation & Verification (DVV).
B5: # | C5: Document | D5: Purpose / What to highlight | E5: FY 2025-26 | F5: FY 2024-25 | G5: FY 2023-24 | H5: FY 2022-23 | I5: Responsibility | J5: File name / Link / Remarks
B6: 1 | C6: Audited Income & Expenditure statement – signed by CA & countersigned by competent authority (MANDATORY) | D6: Highlight capital components; signatures & seal on every year | E6: Pending | F6: Pending | G6: Pending | H6: Pending | I6: Finance Officer
B7: 2 | C7: CA-certified audit extract of capital income and capital expenditure (MANDATORY – Sheet 8 format) | D7: Must match Sheet 5 Section A exactly | E7: Pending | F7: Pending | G7: Pending | H7: Pending | I7: CA / Finance Officer
B8: 3 | C8: Audited Balance Sheet with schedules | D8: Capital fund, corpus, earmarked funds, secured loans | E8: Pending | F8: Pending | G8: Pending | H8: Pending | I8: Finance Office
B9: 4 | C9: Fixed Asset Schedule (Additions & CWIP) | D9: Additions head-wise; CWIP movement | E9: Pending | F9: Pending | G9: Pending | H9: Pending | I9: Finance Office
B10: 5 | C10: Receipts & Payments Account | D10: Capital receipts and payments during the FY | E10: Pending | F10: Pending | G10: Pending | H10: Pending | I10: Finance Office
B11: 6 | C11: Grant sanction letters & Utilisation Certificates | D11: Capital/non-recurring grants received | E11: Pending | F11: Pending | G11: Pending | H11: Pending | I11: Finance / Research Office
B12: 7 | C12: Loan sanction & disbursement advice | D12: Amount disbursed in each FY | E12: Pending | F12: Pending | G12: Pending | H12: Pending | I12: Finance Office
B13: 8 | C13: Trust / Society resolutions & bank credit proof for capital contribution | D13: Amount and purpose of contribution | E13: Pending | F13: Pending | G13: Pending | H13: Pending | I13: Registrar / Finance
B14: 9 | C14: Endowment / donation deeds & CSR agreements | D14: Capital purpose of the receipt | E14: Pending | F14: Pending | G14: Pending | H14: Pending | I14: Finance Office
B15: 10 | C15: Lease agreements & rent receipts | D15: Rentals for academic/hostel premises | E15: Pending | F15: Pending | G15: Pending | H15: Pending | I15: Estate Office
B16: 11 | C16: Purchase orders / work completion certificates for major assets | D16: Supports major capex items | E16: Pending | F16: Pending | G16: Pending | H16: Pending | I16: Purchase / Estate Office
B17: 12 | C17: Explanatory note for years where ratio is outside 0.80x–1.20x | D17: Reason and utilisation plan | E17: Pending | F17: Pending | G17: Pending | H17: Pending | I17: IQAC
C18: Documents Available (count) | E18: =COUNTIF(E6:E17,"Available")&" / "&(12-COUNTIF(E6:E17,"Not Applicable")) -> 0 / 12 | F18: =COUNTIF(F6:F17,"Available")&" / "&(12-COUNTIF(F6:F17,"Not Applicable")) -> 0 / 12 | G18: =COUNTIF(G6:G17,"Available")&" / "&(12-COUNTIF(G6:G17,"Not Applicable")) -> 0 / 12 | H18: =COUNTIF(H6:H17,"Available")&" / "&(12-COUNTIF(H6:H17,"Not Applicable")) -> 0 / 12

Sheet 8. CA Certificate
B2: CERTIFICATE BY CHARTERED ACCOUNTANT
B3: (To be printed on the letterhead of the Chartered Accountant firm)
B5: Ref. No.: ____________________ Date: ____________________
B6: Sub.: Certificate of Capital Income and Capital Expenditure of [University Name] for NAAC Metric 4.1 (Binary Accreditation Framework) – Financial Years 2022-23 to 2025-26
B8: This is to certify that we have verified the audited financial statements (Balance Sheet, Income & Expenditure Account, Receipts & Payments Account and related schedules) of [University Name] for the financial years mentioned below. Based on our verification, the total amount received towards capital (Government grants, management contributions, loans disbursed, endowments etc.) and the total amount spent towards infrastructure (instructional buildings, academic infrastructure including library, hostels, laboratories, equipment, residences, amenities and payment of rentals) are as under:
B10: S. No. | C10: Financial Year | D10: Capital Income (INR Lakhs) | E10: Capital Expenditure (INR Lakhs) | F10: Capital Utilisation Ratio
B11: 1 | C11: FY 2025-26 | D11: ='5. Summary & Ratio'!D7 -> 0 | E11: ='5. Summary & Ratio'!D8 -> 0 | F11: =IF(D11=0,"-",E11/D11) -> -
B12: 2 | C12: FY 2024-25 | D12: ='5. Summary & Ratio'!E7 -> 0 | E12: ='5. Summary & Ratio'!E8 -> 0 | F12: =IF(D12=0,"-",E12/D12) -> -
B13: 3 | C13: FY 2023-24 | D13: ='5. Summary & Ratio'!F7 -> 0 | E13: ='5. Summary & Ratio'!F8 -> 0 | F13: =IF(D13=0,"-",E13/D13) -> -
B14: 4 | C14: FY 2022-23 | D14: ='5. Summary & Ratio'!G7 -> 0 | E14: ='5. Summary & Ratio'!G8 -> 0 | F14: =IF(D14=0,"-",E14/D14) -> -
C15: Total – NAAC period (FY 2023-24 to 2025-26) | D15: =SUM(D11:D13) -> 0 | E15: =SUM(E11:E13) -> 0 | F15: =IF(D15=0,"-",E15/D15) -> -
B17: We further certify that (i) only amounts actually received/disbursed during the respective financial years have been considered as capital income; (ii) capital expenditure comprises additions to fixed assets (including capital work-in-progress) and rentals paid for academic premises, and excludes repairs, maintenance and other revenue items; and (iii) the relevant components have been highlighted in the audited statements enclosed herewith.
B20: For ____________________ (CA Firm Name) | E20: Countersigned by
B21: Chartered Accountants, FRN: __________ | E21: Registrar / Finance Officer
E22: [University Name]
B23: (Signature & Seal) | E23: (Signature & Seal)
B24: Name of Partner: ____________________
B25: Membership No.: __________ UDIN: __________
B27: Place: [City] Enclosures: Highlighted audited statements for FY 2022-23, 2023-24, 2024-25 and 2025-26
