Workbook

Sheet 1. Cover
B2: [UNIVERSITY NAME]
B3: Internal Quality Assurance Cell (IQAC)
B5: NAAC Binary Accreditation Framework | Attribute 4 – Financial Resources & Management (50)
B6: Metric 4.4 – Financial Controls and Risk Management (Weightage: 10)
B7: (a) Internal Audits • (b) External / Statutory Audits • (c) Risk Management Approaches
B8: Data Capture, Compliance & Evidence Workbook • Financial Years 2025-26, 2024-25, 2023-24 and 2022-23
B10: ABSTRACT
B11: This workbook is the institutional tool for preparing NAAC Metric 4.4 – Financial Controls and Risk Management. Like Metric 4.3, it is an options-based metric: the institution must show that mechanisms of financial control are in place through (a) internal audits, (b) external / statutory audits and (c) risk management approaches, supported by audited statements and CA-certified extracts. For four financial years (2025-26, 2024-25, 2023-24 and 2022-23) the workbook records: the internal audit arrangement, frequency, reports issued, areas covered and closure of observations; the statutory audit – auditor, date of audit report, type of audit opinion, compliance of observations and approval of accounts – together with other external audits such as income-tax and GST audits; the risk management approaches implemented each year; and an institutional financial risk register with likelihood-impact scoring. It then automatically evaluates compliance with options (a), (b) and (c), computes control-effectiveness indicators and pre-fills a Chartered Accountant (CA) certificate. Guidelines, a worked example and an evidence checklist are included.
B13: INTRODUCTION
B14: Why this metric matters: Sound financial controls protect the institution's resources, ensure that money is spent only for approved purposes, and give stakeholders – students, parents, regulators, lenders and the sponsoring body – confidence in the integrity of the accounts. NAAC looks for three lines of assurance: (a) Internal Audits – a continuous, independent review (by an in-house audit cell or an external CA firm) of receipts, payments, payroll, procurement, stores, assets, grants and statutory dues, with observations reported to management and closed through action taken reports. (b) External / Statutory Audits – the annual audit of the institution's accounts by an independent Chartered Accountant firm, resulting in an audit report and audited financial statements approved by the Finance Committee and the Board of Management / Governing Body; plus other external audits such as income-tax audit, GST audit and grant audits. (c) Risk Management Approaches – a structured way of identifying, assessing and mitigating financial risks: a risk management policy, a risk register, budgeting and variance control, delegation of financial powers, segregation of duties, insurance, cyber-security, fraud prevention and contingency reserves. Link with other metrics: The audited statements used here are the same ones used for Metrics 4.1, 4.2 and 4.3. Investment controls link with 4.3 (b). Delegation of financial powers links with Metric 7.2, IQAC academic and administrative audits with 7.3, and e-governance in finance with 7.8.
B16: OBJECTIVES OF THIS WORKBOOK
B17: 1. Record internal audit, statutory audit and other external audit details in a standard, year-wise format. 2. Measure control effectiveness – audit coverage, timeliness, audit opinion and closure of observations. 3. Record risk management approaches and maintain a scored financial risk register. 4. Automatically test whether options (a), (b) and (c) can be claimed. 5. Track every supporting document and generate the CA certificate.
B19: WORKBOOK STRUCTURE
B20: Sheet | C20: Purpose | D20: Who fills / uses | E20: Action required
B21: 1. Cover | C21: Abstract, introduction, objectives and structure | D21: All users | E21: Read first
B22: 2. Guidelines | C22: What NAAC asks, compliance tests, procedure, definitions, indicators, documents, common errors | D22: Finance Office & IQAC | E22: Read before entering data
B23: 3. Internal Audit | C23: Internal audit arrangement, reports, observations and area coverage – FY-wise | D23: Finance Office / Internal Auditor | E23: Enter data in cream cells
B24: 4. Statutory & External Audit | C24: Statutory audit details, opinion, timeliness, compliance; other external audits | D24: Finance Office | E24: Enter data in cream cells
B25: 5. Risk Mgmt Approaches | C25: Status of 12 risk management approaches – FY-wise | D25: Finance Officer & IQAC | E25: Select status from drop-down
B26: 6. Risk Register | C26: Financial risks with likelihood × impact scoring, mitigation and owner | D26: Finance Officer / Risk Committee | E26: Score and update
B27: 7. Summary & Compliance | C27: Option (a), (b), (c) compliance, indicators and chart | D27: IQAC (auto-calculated) | E27: Review only
B28: 8. Worked Example | C28: Illustration with hypothetical data | D28: Training / reference | E28: Read only
B29: 9. Document Checklist | C29: Status of every supporting document, FY-wise | D29: IQAC & Finance Office | E29: Select status
B30: 10. CA Certificate | C30: Certificate format pre-filled from the Summary | D30: CA / Finance Officer | E30: Print, verify and sign
B32: CELL COLOUR LEGEND
B33: Cream fill, blue text | C33: Input cell – enter data / select from drop-down
B34: Light navy fill, black text | C34: Formula – do not overwrite
B35: Green text | C35: Value linked from another sheet – do not overwrite
B36: Navy fill, gold/white text | C36: Headings and sections
B38: Prepared by: IQAC, [University Name] | Version 1.0 | Basis: NAAC Binary Accreditation Framework – Metrics for Manual (Base), Draft Version
B39: Note: The NAAC draft lists the three options but does not publish the scoring method. Compliance tests and bands in this workbook are indicative IQAC guidance; update them when NAAC notifies the final SOP.

Sheet 2. Guidelines
B2: GUIDELINES FOR PREPARING METRIC 4.4
B3: G1. WHAT NAAC ASKS
B4: Option | C4: Mechanism | D4: What it means | E4: Evidence
B5: a | C5: Internal audits | D5: An internal auditor (in-house audit cell or external CA firm) is appointed and conducts periodic audits of financial transactions and controls; observations are reported and closed through Action Taken Reports (ATR) | E5: Internal auditor appointment letter, internal audit reports, ATR, Finance / Audit Committee minutes
B6: b | C6: External / statutory audits | D6: Annual accounts are audited by an independent CA firm; audit report issued; audited accounts approved by Finance Committee and BOM / Governing Body; other external audits (income-tax, GST, grant audits) conducted | E6: Audited statements signed by CA and countersigned by competent authority; CA-certified audit extracts; approval minutes
B7: c | C7: Risk management approaches | D7: A documented approach to identify, assess and mitigate financial risks – policy, committee, risk register, budgetary control, delegation of powers, insurance, cyber-security, fraud prevention, contingency reserve | E7: Risk management policy, risk register, committee minutes, insurance policies, delegation-of-powers ordinance
B9: G2. YEAR BASIS
B10: • Use FINANCIAL YEARS (1 April – 31 March). • NAAC assessment period = FY 2025-26, FY 2024-25 and FY 2023-24. FY 2022-23 is captured as a baseline for trend comparison. • The statutory audit of a financial year is normally completed in the following months – e.g., the audit report for FY 2025-26 is dated after 31 March 2026. Record it against the FY whose accounts were audited. • Enter dates as dd-mm-yyyy; they will display as dd-mmm-yyyy.
B12: G3. COMPLIANCE TESTS USED IN THIS WORKBOOK (INDICATIVE)
B13: Option | C13: Test applied | D13: Result shown | E13: Notes
B14: a | C14: At least one internal audit report issued in each of the three NAAC years | D14: YES / PARTIAL (n of 3 years) / NO | E14: Strength shown by frequency, area coverage and observation closure %
B15: b | C15: Statutory audit report dated for each of the three NAAC years | D15: YES / PARTIAL / NO | E15: Strength shown by audit opinion (Unqualified is best), days from year-end to audit report, and closure of observations
B16: c | C16: Number of risk management approaches 'Implemented' in FY 2025-26: 6 or more of 12 = YES; 1–5 = PARTIAL; 0 = NO | D16: YES / PARTIAL / NO | E16: A board-approved Risk Management Policy and a maintained risk register strengthen the claim
B18: G4. STEP-BY-STEP PROCEDURE
B19: Step | C19: Activity | D19: How to do it | E19: Responsibility / Output
B20: 1 | C20: Internal audit details | D20: From the internal auditor's appointment letter and reports, enter arrangement, frequency, reports issued and observations for each FY (Sheet 3) | E20: Finance Office / Internal Auditor
B21: 2 | C21: Area coverage | D21: Mark Yes/No for each of the 12 audit areas covered in each FY | E21: Internal Auditor
B22: 3 | C22: Statutory audit details | D22: From the audited accounts and audit report, enter auditor, FRN, report date, opinion, observations and approval dates (Sheet 4) | E22: Finance Office
B23: 4 | C23: Other external audits | D23: Mark Yes / No / NA for income-tax audit, GST, grant and other audits | E23: Finance Office
B24: 5 | C24: Risk approaches | D24: For each FY, select the status of each of the 12 approaches (Sheet 5) and note evidence | E24: Finance Officer & IQAC
B25: 6 | C25: Risk register | D25: Score each risk for likelihood and impact (1–5); describe mitigation and owner (Sheet 6) | E25: Finance Officer / Risk Committee
B26: 7 | C26: Review | D26: Check Sheet 7 – option status, indicators, pending observations | E26: IQAC Director
B27: 8 | C27: CA certificate | D27: Print Sheet 10; CA verifies and signs; Registrar / Finance Officer countersigns | E27: CA & competent authority
B28: 9 | C28: Upload | D28: Select options met on the NAAC portal; upload CA certificate, audited statements and supporting evidence | E28: IQAC
B30: G5. INDICATORS COMPUTED
B31: # | C31: Indicator | D31: Formula | E31: Indicative benchmark
B32: 1 | C32: Internal audit observation closure % | D32: Observations complied ÷ Observations raised | E32: ≥ 90% strong; 75–89% adequate; < 75% needs attention
B33: 2 | C33: Internal audit area coverage % | D33: Areas covered ÷ 12 areas | E33: ≥ 80% strong
B34: 3 | C34: Days from year-end to statutory audit report | D34: Audit report date – 31 March of the FY | E34: ≤ 180 days preferred (timely closing of accounts)
B35: 4 | C35: Statutory audit observation closure % | D35: Observations complied ÷ Observations raised | E35: ≥ 90% strong
B36: 5 | C36: Audit opinion | D36: As stated in the audit report | E36: Unqualified (clean) opinion is the expected standard
B37: 6 | C37: Risk approaches implemented | D37: Count of 'Implemented' out of 12 | E37: ≥ 6 = option (c) met
B38: 7 | C38: Risk score | D38: Likelihood (1–5) × Impact (1–5) | E38: 15–25 High; 8–14 Medium; 1–7 Low
B40: G6. SUPPORTING DOCUMENTS REQUIRED BY NAAC
B41: 1. Audited Income & Expenditure statement of the institution highlighting the specific components, certified by the CA. 2. Audit extracts of the same, certified by the CA (use Sheet 10). Recommended additional evidence: internal auditor appointment letter and scope; internal audit reports and ATRs; statutory auditor appointment resolution; audit reports with management replies; Finance Committee and BOM minutes approving audited accounts; income-tax audit report (Form 10B / 10BB), GST reconciliation; risk management policy, risk register, Audit / Risk Committee minutes; delegation of financial powers ordinance; insurance policies. Track these in Sheet 9.
B43: G7. COMMON ERRORS AND HOW TO AVOID THEM
B44: # | C44: Error | D44: Consequence | E44: Prevention
B45: 1 | C45: Treating the IQAC Academic & Administrative Audit (AAA) as a financial internal audit | D45: Option (a) weak or rejected | E45: AAA belongs to Metric 7.3; financial internal audit must be by a qualified internal auditor
B46: 2 | C46: Internal audit reports without ATR / closure evidence | D46: Control effectiveness not demonstrated | E46: Maintain ATR for every report and place it before the Finance / Audit Committee
B47: 3 | C47: Audited accounts not countersigned or not approved by BOM | D47: Document treated as incomplete | E47: Record approval dates in Sheet 4
...

Sheet 3. Internal Audit
B2: SHEET 3 – INTERNAL AUDIT (OPTION a)
B3: Record the internal audit arrangement and its outcomes for each financial year. Use numbers for counts, select Yes/No from drop-downs and enter dates as dd-mm-yyyy. Source: internal auditor appointment letter, internal audit reports, Action Taken Reports (ATR) and Finance / Audit Committee minutes.
B5: Code | C5: Parameter | D5: FY 2025-26 | E5: FY 2024-25 | F5: FY 2023-24 | G5: FY 2022-23 | H5: NAAC 3-Yr | I5: Evidence Reference | J5: Remarks
B6: A | C6: Internal audit arrangement
B7: IA1 | C7: Internal auditor appointed? (Yes / No)
B8: IA2 | C8: Internal auditor – name & type (in-house audit cell / external CA firm)
B9: IA3 | C9: Date of appointment / engagement letter
B10: IA4 | C10: Frequency of internal audit
B11: B | C11: Internal audit outcomes
B12: IA5 | C12: Number of internal audit reports issued during the FY | H12: =SUM(D12:F12) -> 0
B13: IA6 | C13: Number of observations raised | H13: =SUM(D13:F13) -> 0
B14: IA7 | C14: Number of observations complied / closed | H14: =SUM(D14:F14) -> 0
B15: IA8 | C15: Pending observations (IA6 – IA7) | D15: =N(D13)-N(D14) -> 0 | E15: =N(E13)-N(E14) -> 0 | F15: =N(F13)-N(F14) -> 0 | G15: =N(G13)-N(G14) -> 0 | H15: =N(H13)-N(H14) -> 0
B16: IA9 | C16: Observation closure % (IA7 ÷ IA6) | D16: =IF(N(D13)=0,"-",D14/D13) -> - | E16: =IF(N(E13)=0,"-",E14/E13) -> - | F16: =IF(N(F13)=0,"-",F14/F13) -> - | G16: =IF(N(G13)=0,"-",G14/G13) -> - | H16: =IF(N(H13)=0,"-",H14/H13) -> -
B17: IA10 | C17: Internal audit reports & ATR placed before Finance / Audit Committee? (Yes / No)
B18: IA11 | C18: Date of Finance / Audit Committee meeting that reviewed internal audit
B20: C | C20: Audit areas covered during the FY (select Yes / No)
B21: C1 | C21: Fee collection & receipts
B22: C2 | C22: Payroll & salary disbursement
B23: C3 | C23: Purchases & procurement
B24: C4 | C24: Stores & inventory
B25: C5 | C25: Fixed assets & capital works
B26: C6 | C26: Investments & corpus (link 4.3)
B27: C7 | C27: Research grants & projects
B28: C8 | C28: Hostel, mess & canteen
B29: C9 | C29: Examination finance
... B32: C12 | C32: Scholarships, freeships & refunds
B33: C | C33: Areas covered (count of 12) | D33: =COUNTIF(D21:D32,"Yes") -> 0 | E33: =COUNTIF(E21:E32,"Yes") -> 0 | F33: =COUNTIF(F21:F32,"Yes") -> 0 | G33: =COUNTIF(G21:G32,"Yes") -> 0
B34: C% | C34: Area coverage % | D34: =D33/12 -> 0 | E34: =E33/12 -> 0 | F34: =F33/12 -> 0 | G34: =G33/12 -> 0
B36: Filling rules: (1) Cream cells only. (2) Counts as whole numbers; dates as dd-mm-yyyy. (3) The IQAC Academic & Administrative Audit is NOT a financial internal audit – do not record it here. (4) Give the report / minute reference in 'Evidence Reference'.

Sheet 4. Statutory & External Audit
B2: SHEET 4 – STATUTORY & OTHER EXTERNAL AUDITS (OPTION b)
B3: Record statutory audit details against the financial year whose accounts were audited (e.g., audit report dated September 2026 for FY 2025-26). Source: audited financial statements, auditor's report, appointment resolution, Finance Committee and BOM minutes, income-tax and GST audit reports.
B5: Code | C5: Parameter | D5: FY 2025-26 | E5: FY 2024-25 | F5: FY 2023-24 | G5: FY 2022-23 | H5: NAAC 3-Yr | I5: Evidence Reference | J5: Remarks
B6: A | C6: Statutory audit
B7: SA1 | C7: Statutory auditor – CA firm name
B8: SA2 | C8: Firm Registration Number (FRN)
B9: SA3 | C9: Appointed by (Body) – e.g., Governing Body / BOM / Trust
B10: SA4 | C10: Date of statutory audit report
B11: SA5 | C11: Days from FY end (31 March) to audit report | D11: =IF(D10="","-",D10-DATE(2026,3,31)) -> - | E11: =IF(E10="","-",E10-DATE(2025,3,31)) -> - | F11: =IF(F10="","-",F10-DATE(2024,3,31)) -> - | G11: =IF(G10="","-",G10-DATE(2023,3,31)) -> - | H11: =IFERROR(AVERAGE(D11:F11),"-") -> -
B12: SA6 | C12: Type of audit opinion
B13: SA7 | C13: Number of audit observations / qualifications | H13: =SUM(D13:F13) -> 0
B14: SA8 | C14: Number of observations complied | H14: =SUM(D14:F14) -> 0
B15: SA9 | C15: Pending observations (SA7 – SA8) | D15: =N(D13)-N(D14) -> 0 | E15: =N(E13)-N(E14) -> 0 | F15: =N(F13)-N(F14) -> 0 | G15: =N(G13)-N(G14) -> 0 | H15: =N(H13)-N(H14) -> 0
B16: SA10 | C16: Observation closure % (SA8 ÷ SA7) | D16: =IF(N(D13)=0,"-",D14/D13) -> - | E16: =IF(N(E13)=0,"-",E14/E13) -> - | F16: =IF(N(F13)=0,"-",F14/F13) -> - | G16: =IF(N(G13)=0,"-",G14/G13) -> - | H16: =IF(N(H13)=0,"-",H14/H13) -> -
B17: SA11 | C17: Date audited accounts approved by Finance Committee
B18: SA12 | C18: Date audited accounts approved by BOM / Governing Body
B19: SA13 | C19: Audited accounts submitted to regulator / hosted on website? (Yes / No)
B21: B | C21: Other external audits (select Yes / No / Not Applicable)
B22: B1 | C22: Income-tax audit (Form 10B / 10BB)
B23: B2 | C23: GST audit / annual reconciliation
B24: B3 | C24: Audit / Utilisation Certificates of grants by funding agencies
B25: B4 | C25: Government / State audit (if applicable)
B26: B5 | C26: Any other external financial audit (specify)
B27: B | C27: Other external audits conducted (count) | D27: =COUNTIF(D22:D26,"Yes") -> 0 | E27: =COUNTIF(E22:E26,"Yes") -> 0 | F27: =COUNTIF(F22:F26,"Yes") -> 0 | G27: =COUNTIF(G22:G26,"Yes") -> 0
B29: Filling rules: (1) Cream cells only. (2) Dates as dd-mm-yyyy. (3) If the opinion is not Unqualified, attach the management reply and corrective action. (4) Give the page / minute reference in 'Evidence Reference'.

Sheet 5. Risk Mgmt Approaches
B2: SHEET 5 – RISK MANAGEMENT APPROACHES (OPTION c)
B3: For each financial year, select the status of each approach: Implemented / Partially implemented / Not implemented / Not applicable. 'Implemented' means a documented, approved mechanism that is actually operating, with evidence for that year.
B5: # | C5: Risk management approach | D5: FY 2025-26 | E5: FY 2024-25 | F5: FY 2023-24 | G5: FY 2022-23 | H5: Evidence (policy / minutes / document)
B6: 1 | C6: Risk Management Policy approved by BOM / Governing Body
B7: 2 | C7: Risk Management / Audit Committee constituted and meeting
B8: 3 | C8: Institutional financial risk register maintained & reviewed (Sheet 6)
B9: 4 | C9: Annual budget with periodic budget-vs-actual variance review
B10: 5 | C10: Delegation of financial powers & approval hierarchy (ordinance / SOP)
B11: 6 | C11: Segregation of duties / maker-checker controls in ERP / accounting system
B12: 7 | C12: Investment policy with exposure limits per instrument & bank (link 4.3)
B13: 8 | C13: Insurance cover – assets, students, staff, liability
B14: 9 | C14: Cyber-security, data backup & access controls for finance systems
B15: 10 | C15: Fraud prevention, whistle-blower & vigilance mechanism
B16: 11 | C16: Statutory compliance calendar – TDS, GST, PF, ESI, returns
B17: 12 | C17: Contingency / reserve fund & business continuity plan (link 4.3)
C18: Approaches 'Implemented' (count of 12) | D18: =COUNTIF(D6:D17,"Implemented") -> 0 | E18: =COUNTIF(E6:E17,"Implemented") -> 0 | F18: =COUNTIF(F6:F17,"Implemented") -> 0 | G18: =COUNTIF(G6:G17,"Implemented") -> 0
C19: Approaches 'Partially implemented' (count) | D19: =COUNTIF(D6:D17,"Partially implemented") -> 0 | E19: =COUNTIF(E6:E17,"Partially implemented") -> 0 | F19: =COUNTIF(F6:F17,"Partially implemented") -> 0 | G19: =COUNTIF(G6:G17,"Partially implemented") -> 0

Sheet 6. Risk Register
B2: SHEET 6 – INSTITUTIONAL FINANCIAL RISK REGISTER
B3: Score each risk for Likelihood and Impact on a 1–5 scale (1 = very low, 5 = very high). Score = Likelihood × Impact; Rating: 15–25 High, 8–14 Medium, 1–7 Low. The risks and mitigations listed are typical for a private university – edit the grey text to reflect [University Name]'s own assessment and add rows as needed. Review the register at least once a year and record the review date below.
B5: # | C5: Risk description | D5: Category | E5: Likelihood (1–5) | F5: Impact (1–5) | G5: Score | H5: Rating | I5: Mitigation / control measures | J5: Risk owner | K5: Status
B6: 1 | C6: Shortfall in admissions / fee revenue | D6: Revenue | G6: =IF(OR(E6="",F6=""),"-",E6*F6) -> - | H6: =IF(G6="-","-",IF(G6>=15,"High",IF(G6>=8,"Medium","Low"))) -> - | I6: Programme review, outreach, diversified income (consultancy, training) | J6: Registrar / Admissions | K6: Open
B7: 2 | C7: Delays / defaults in fee receivables & reimbursements | D7: Liquidity | G7: =IF(OR(E7="",F7=""),"-",E7*F7) -> - | H7: =IF(G7="-","-",IF(G7>=15,"High",IF(G7>=8,"Medium","Low"))) -> - | I7: Fee-collection calendar, follow-up of government reimbursements, receivables ageing review | J7: Finance Officer | K7: Open
B8: 3 | C8: Cost escalation – salaries, utilities, maintenance | D8: Expenditure | G8: =IF(OR(E8="",F8=""),"-",E8*F8) -> - | H8: =IF(G8="-","-",IF(G8>=15,"High",IF(G8>=8,"Medium","Low"))) -> - | I8: Annual budget, variance review, energy conservation, centralised procurement | J8: Finance Officer | K8: Open
B9: 4 | C9: Credit / default risk of banks or instruments where funds are invested | D9: Investment | G9: =IF(OR(E9="",F9=""),"-",E9*F9) -> - | H9: =IF(G9="-","-",IF(G9>=15,"High",IF(G9>=8,"Medium","Low"))) -> - | I9: Investment policy limits, rated instruments, spread across banks (Metric 4.3) | J9: Finance Committee | K9: Open
B10: 5 | C10: Fraud, misappropriation or unauthorised payments | D10: Control | G10: =IF(OR(E10="",F10=""),"-",E10*F10) -> - | H10: =IF(G10="-","-",IF(G10>=15,"High",IF(G10>=8,"Medium","Low"))) -> - | I10: Maker-checker in ERP, delegation of powers, internal audit, whistle-blower policy | J10: Finance Officer / Internal Auditor | K10: Open
B11: 6 | C11: Non-compliance with tax / statutory dues (TDS, GST, PF) | D11: Compliance | G11: =IF(OR(E11="",F11=""),"-",E11*F11) -> - | H11: =IF(G11="-","-",IF(G11>=15,"High",IF(G11>=8,"Medium","Low"))) -> - | I11: Compliance calendar, monthly reconciliations, tax audit | J11: Accounts Head | K11: Open
B12: 7 | C12: Loss or breach of financial data / ERP failure | D12: Technology | G12: =IF(OR(E12="",F12=""),"-",E12*F12) -> - | H12: =IF(G12="-","-",IF(G12>=15,"High",IF(G12>=8,"Medium","Low"))) -> - | I12: Access controls, backups, cyber-security audit, disaster recovery | J12: IT Head | K12: Open
B13: 8 | C13: Loan repayment / liquidity mismatch | D13: Liquidity | G13: =IF(OR(E13="",F13=""),"-",E13*F13) -> - | H13: =IF(G13="-","-",IF(G13>=15,"High",IF(G13>=8,"Medium","Low"))) -> - | I13: Cash-flow forecasting, sinking / contingency fund | J13: Finance Officer | K13: Open
B14: 9 | C14: Non-utilisation or disallowance of grants | D14: Compliance | G14: =IF(OR(E14="",F14=""),"-",E14*F14) -> - | H14: =IF(G14="-","-",IF(G14>=15,"High",IF(G14>=8,"Medium","Low"))) -> - | I14: Grant tracking, timely Utilisation Certificates, project audit | J14: Research Office | K14: Open
B15: 10 | C15: Damage or loss of assets (fire, theft, natural events) | D15: Operational | G15: =IF(OR(E15="",F15=""),"-",E15*F15) -> - | H15: =IF(G15="-","-",IF(G15>=15,"High",IF(G15>=8,"Medium","Low"))) -> - | I15: Insurance cover, safety audit, asset register verification | J15: Estate Officer | K15: Open
B16: 11 | G16: =IF(OR(E16="",F16=""),"-",E16*F16) -> - | H16: =IF(G16="-","-",IF(G16>=15,"High",IF(G16>=8,"Medium","Low"))) -> -
B17: 12 | G17: =IF(OR(E17="",F17=""),"-",E17*F17) -> - | H17: =IF(G17="-","-",IF(G17>=15,"High",IF(G17>=8,"Medium","Low"))) -> -
B18: 13 | G18: =IF(OR(E18="",F18=""),"-",E18*F18) -> - | H18: =IF(G18="-","-",IF(G18>=15,"High",IF(G18>=8,"Medium","Low"))) -> -
B19: 14 | G19: =IF(OR(E19="",F19=""),"-",E19*F19) -> - | H19: =IF(G19="-","-",IF(G19>=15,"High",IF(G19>=8,"Medium","Low"))) -> -
B20: 15 | G20: =IF(OR(E20="",F20=""),"-",E20*F20) -> - | H20: =IF(G20="-","-",IF(G20>=15,"High",IF(G20>=8,"Medium","Low"))) -> -
C22: High risks | G22: =COUNTIF(H6:H20,"High") -> 0
C23: Medium risks | G23: =COUNTIF(H6:H20,"Medium") -> 0
C24: Low risks | G24: =COUNTIF(H6:H20,"Low") -> 0
C25: Risks scored (total) | G25: =COUNT(G6:G20) -> 0
C27: Date of last review of risk register (input) | I27: Reviewed by (Committee):

Sheet 7. Summary & Compliance
B2: SHEET 7 – SUMMARY, OPTION COMPLIANCE & CONTROL INDICATORS
B3: This sheet is fully formula-driven from Sheets 3 to 6 – do not type here. Section A shows whether options (a), (b) and (c) can be claimed on the NAAC portal; Sections B to D show how strong each mechanism is.
B5: A. NAAC OPTION COMPLIANCE (ASSESSMENT PERIOD FY 2023-24 TO 2025-26)
B6: Option | C6: Mechanism | D6: Status for NAAC | H6: Basis
B7: (a) | C7: Internal audits | D7: =IF(COUNTIF('3. Internal Audit'!D12:F12,">0")=3,"YES – Internal audit in all 3 years ("&'3. Internal Audit'!H12&" reports)",IF(COUNTIF('3. Internal Audit'!D12:F12,">0")>0,"PARTIAL – Internal audit in "&COUNTIF('3. Internal Audit'!D12:F12,">0")&" of 3 years","NO – No internal audit recorded")) -> NO – No internal audit recorded | H7: ≥ 1 internal audit report in each NAAC year
B8: (b) | C8: External / statutory audits | D8: =IF(COUNT('4. Statutory & External Audit'!D10:F10)=3,"YES – Statutory audit in all 3 years (latest opinion: "&IF('4. Statutory & External Audit'!D12="","not entered",'4. Statutory & External Audit'!D12)&")",IF(COUNT('4. Statutory & External Audit'!D10:F10)>0,"PARTIAL – Audit report dated for "&COUNT('4. Statutory & External Audit'!D10:F10)&" of 3 years","NO – No audit report date recorded")) -> NO – No audit report date recorded | H8: Audit report dated for each NAAC year
B9: (c) | C9: Risk management approaches | D9: =IF('5. Risk Mgmt Approaches'!D18>=6,"YES – "&'5. Risk Mgmt Approaches'!D18&" of 12 approaches implemented (FY 2025-26)",IF('5. Risk Mgmt Approaches'!D18>0,"PARTIAL – "&'5. Risk Mgmt Approaches'!D18&" of 12 approaches implemented","NO – No approach implemented")) -> NO – No approach implemented | H9: ≥ 6 of 12 approaches implemented in FY 2025-26
C10: Options fully met (out of 3) | D10: =(LEFT(D7,3)="YES")+(LEFT(D8,3)="YES")+(LEFT(D9,3)="YES")&" of 3" -> 0 of 3
B12: B. OPTION (a) – INTERNAL AUDIT INDICATORS
B13: # | C13: Indicator | D13: FY 2025-26 | E13: FY 2024-25 | F13: FY 2023-24 | G13: FY 2022-23 | H13: NAAC 3-Yr
B14: B1 | C14: Internal auditor appointed | D14: =IF('3. Internal Audit'!D7="","-",'3. Internal Audit'!D7) -> - | E14: =IF('3. Internal Audit'!E7="","-",'3. Internal Audit'!E7) -> - | F14: =IF('3. Internal Audit'!F7="","-",'3. Internal Audit'!F7) -> - | G14: =IF('3. Internal Audit'!G7="","-",'3. Internal Audit'!G7) -> - | H14: —
B15: B2 | C15: Frequency | D15: =IF('3. Internal Audit'!D10="","-",'3. Internal Audit'!D10) -> - | E15: =IF('3. Internal Audit'!E10="","-",'3. Internal Audit'!E10) -> - | F15: =IF('3. Internal Audit'!F10="","-",'3. Internal Audit'!F10) -> - | G15: =IF('3. Internal Audit'!G10="","-",'3. Internal Audit'!G10) -> - | H15: —
B16: B3 | C16: Internal audit reports issued | D16: =N('3. Internal Audit'!D12) -> 0 | E16: =N('3. Internal Audit'!E12) -> 0 | F16: =N('3. Internal Audit'!F12) -> 0 | G16: =N('3. Internal Audit'!G12) -> 0 | H16: =SUM(D16:F16) -> 0
B17: B4 | C17: Observations raised | D17: =N('3. Internal Audit'!D13) -> 0 | E17: =N('3. Internal Audit'!E13) -> 0 | F17: =N('3. Internal Audit'!F13) -> 0 | G17: =N('3. Internal Audit'!G13) -> 0 | H17: =SUM(D17:F17) -> 0
B18: B5 | C18: Observations complied | D18: =N('3. Internal Audit'!D14) -> 0 | E18: =N('3. Internal Audit'!E14) -> 0 | F18: =N('3. Internal Audit'!F14) -> 0 | G18: =N('3. Internal Audit'!G14) -> 0 | H18: =SUM(D18:F18) -> 0
B19: B6 | C19: Observation closure % | D19: =IF(D17=0,"-",D18/D17) -> - | E19: =IF(E17=0,"-",E18/E17) -> - | F19: =IF(F17=0,"-",F18/F17) -> - | G19: =IF(G17=0,"-",G18/G17) -> - | H19: =IF(H17=0,"-",H18/H17) -> -
B20: B7 | C20: Audit area coverage % | D20: ='3. Internal Audit'!D34 -> 0 | E20: ='3. Internal Audit'!E34 -> 0 | F20: ='3. Internal Audit'!F34 -> 0 | G20: ='3. Internal Audit'!G34 -> 0 | H20: —
B21: B8 | C21: ATR placed before Finance / Audit Committee | D21: =IF('3. Internal Audit'!D17="","-",'3. Internal Audit'!D17) -> - | E21: =IF('3. Internal Audit'!E17="","-",'3. Internal Audit'!E17) -> - | F21: =IF('3. Internal Audit'!F17="","-",'3. Internal Audit'!F17) -> - | G21: =IF('3. Internal Audit'!G17="","-",'3. Internal Audit'!G17) -> - | H21: —
B22: B9 | C22: Interpretation – internal audit effectiveness | D22: =IF(D19="-","Enter data",IF(D19>=0.9,"Strong (≥ 90% closure)",IF(D19>=0.75,"Adequate (75–89%)","Needs attention (< 75%)"))) -> Enter data | E22: =IF(E19="-","Enter data",IF(E19>=0.9,"Strong (≥ 90% closure)",IF(E19>=0.75,"Adequate (75–89%)","Needs attention (< 75%)"))) -> Enter data | F22: =IF(F19="-","Enter data",IF(F19>=0.9,"Strong (≥ 90% closure)",IF(F19>=0.75,"Adequate (75–89%)","Needs attention (< 75%)"))) -> Enter data | G22: =IF(G19="-","Enter data",IF(G19>=0.9,"Strong (≥ 90% closure)",IF(G19>=0.75,"Adequate (75–89%)","Needs attention (< 75%)"))) -> Enter data
B24: C. OPTION (b) – STATUTORY & EXTERNAL AUDIT INDICATORS
B25: # | C25: Indicator | D25: FY 2025-26 | E25: FY 2024-25 | F25: FY 2023-24 | G25: FY 2022-23 | H25: NAAC 3-Yr
B26: C1 | C26: Date of statutory audit report | D26: =IF('4. Statutory & External Audit'!D10="","-",'4. Statutory & External Audit'!D10) -> - | E26: =IF('4. Statutory & External Audit'!E10="","-",'4. Statutory & External Audit'!E10) -> - | F26: =IF('4. Statutory & External Audit'!F10="","-",'4. Statutory & External Audit'!F10) -> - | G26: =IF('4. Statutory & External Audit'!G10="","-",'4. Statutory & External Audit'!G10) -> - | H26: —
B27: C2 | C27: Days from FY end to audit report | D27: ='4. Statutory & External Audit'!D11 -> - | E27: ='4. Statutory & External Audit'!E11 -> - | F27: ='4. Statutory & External Audit'!F11 -> - | G27: ='4. Statutory & External Audit'!G11 -> - | H27: =IFERROR(AVERAGE(D27:F27),"-") -> -
B28: C3 | C28: Audit opinion | D28: =IF('4. Statutory & External Audit'!D12="","-",'4. Statutory & External Audit'!D12) -> - | E28: =IF('4. Statutory & External Audit'!E12="","-",'4. Statutory & External Audit'!E12) -> - | F28: =IF('4. Statutory & External Audit'!F12="","-",'4. Statutory & External Audit'!F12) -> - | G28: =IF('4. Statutory & External Audit'!G12="","-",'4. Statutory & External Audit'!G12) -> - | H28: —
B29: C4 | C29: Audit observations raised | D29: =N('4. Statutory & External Audit'!D13) -> 0 | E29: =N('4. Statutory & External Audit'!E13) -> 0 | F29: =N('4. Statutory & External Audit'!F13) -> 0 | G29: =N('4. Statutory & External Audit'!G13) -> 0 | H29: =SUM(D29:F29) -> 0
B30: C5 | C30: Audit observations complied | D30: =N('4. Statutory & External Audit'!D14) -> 0 | E30: =N('4. Statutory & External Audit'!E14) -> 0 | F30: =N('4. Statutory & External Audit'!F14) -> 0 | G30: =N('4. Statutory & External Audit'!G14) -> 0 | H30: =SUM(D30:F30) -> 0
B31: C6 | C31: Observation closure % | D31: =IF(D29=0,"-",D30/D29) -> - | E31: =IF(E29=0,"-",E30/E29) -> - | F31: =IF(F29=0,"-",F30/F29) -> - | G31: =IF(G29=0,"-",G30/G29) -> - | H31: =IF(H29=0,"-",H30/H29) -> -
B32: C7 | C32: Audited accounts approved by BOM / Governing Body on | D32: =IF('4. Statutory & External Audit'!D18="","-",'4. Statutory & External Audit'!D18) -> - | E32: =IF('4. Statutory & External Audit'!E18="","-",'4. Statutory & External Audit'!E18) -> - | F32: =IF('4. Statutory & External Audit'!F18="","-",'4. Statutory & External Audit'!F18) -> - | G32: =IF('4. Statutory & External Audit'!G18="","-",'4. Statutory & External Audit'!G18) -> - | H32: —
B33: C8 | C33: Other external audits conducted (count) | D33: ='4. Statutory & External Audit'!D27 -> 0 | E33: ='4. Statutory & External Audit'!E27 -> 0 | F33: ='4. Statutory & External Audit'!F27 -> 0 | G33: ='4. Statutory & External Audit'!G27 -> 0 | H33: —
B34: C9 | C34: Interpretation – timeliness (indicative) | D34: =IF(N(D27)=0,"Enter data",IF(D27<=180,"Timely (≤ 180 days)","Delayed (> 180 days)")) -> Enter data | E34: =IF(N(E27)=0,"Enter data",IF(E27<=180,"Timely (≤ 180 days)","Delayed (> 180 days)")) -> Enter data | F34: =IF(N(F27)=0,"Enter data",IF(F27<=180,"Timely (≤ 180 days)","Delayed (> 180 days)")) -> Enter data | G34: =IF(N(G27)=0,"Enter data",IF(G27<=180,"Timely (≤ 180 days)","Delayed (> 180 days)")) -> Enter data
B36: D. OPTION (c) – RISK MANAGEMENT INDICATORS
B37: # | C37: Indicator | D37: FY 2025-26 | E37: FY 2024-25 | F37: FY 2023-24 | G37: FY 2022-23 | H37: NAAC 3-Yr
B38: D1 | C38: Approaches implemented (of 12) | D38: ='5. Risk Mgmt Approaches'!D18 -> 0 | E38: ='5. Risk Mgmt Approaches'!E18 -> 0 | F38: ='5. Risk Mgmt Approaches'!F18 -> 0 | G38: ='5. Risk Mgmt Approaches'!G18 -> 0 | H38: —
B39: D2 | C39: Approaches partially implemented | D39: ='5. Risk Mgmt Approaches'!D19 -> 0 | E39: ='5. Risk Mgmt Approaches'!E19 -> 0 | F39: ='5. Risk Mgmt Approaches'!F19 -> 0 | G39: ='5. Risk Mgmt Approaches'!G19 -> 0 | H39: —
B40: D3 | C40: Risk Management Policy status | D40: =IF('5. Risk Mgmt Approaches'!D6="","-",'5. Risk Mgmt Approaches'!D6) -> - | E40: =IF('5. Risk Mgmt Approaches'!E6="","-",'5. Risk Mgmt Approaches'!E6) -> - | F40: =IF('5. Risk Mgmt Approaches'!F6="","-",'5. Risk Mgmt Approaches'!F6) -> - | G40: =IF('5. Risk Mgmt Approaches'!G6="","-",'5. Risk Mgmt Approaches'!G6) -> - | H40: —
B41: D4 | C41: Interpretation (indicative) | D41: =IF(D38>=9,"Comprehensive (9–12)",IF(D38>=6,"Established (6–8)",IF(D38>=1,"Developing (1–5)","Not in place"))) -> Not in place | E41: =IF(E38>=9,"Comprehensive (9–12)",IF(E38>=6,"Established (6–8)",IF(E38>=1,"Developing (1–5)","Not in place"))) -> Not in place | F41: =IF(F38>=9,"Comprehensive (9–12)",IF(F38>=6,"Established (6–8)",IF(F38>=1,"Developing (1–5)","Not in place"))) -> Not in place | G41: =IF(G38>=9,"Comprehensive (9–12)",IF(G38>=6,"Established (6–8)",IF(G38>=1,"Developing (1–5)","Not in place"))) -> Not in place
B43: # | C43: Current risk register (Sheet 6) | D43: Count
B44: R1 | C44: High risks (score 15–25) | D44: ='6. Risk Register'!G22 -> 0
B45: R2 | C45: Medium risks (score 8–14) | D45: ='6. Risk Register'!G23 -> 0
B46: R3 | C46: Low risks (score 1–7) | D46: ='6. Risk Register'!G24 -> 0
...

Sheet 8. Worked Example
B2: SHEET 8 – WORKED EXAMPLE (HYPOTHETICAL DATA – FOR UNDERSTANDING ONLY)
B3: The data below is purely illustrative and does NOT represent any institution. It shows how the entries in Sheets 3 to 6 translate into option status and indicators.
B5: Step 1 – Internal audit
B6: Code | C6: Particulars | D6: FY 2025-26 | E6: FY 2024-25 | F6: FY 2023-24 | G6: FY 2022-23 | H6: NAAC 3-Yr
B7: IA4 | C7: Frequency | D7: Quarterly | E7: Quarterly | F7: Quarterly | G7: Half-yearly
B8: IA5 | C8: Reports issued | D8: 4 | E8: 4 | F8: 4 | G8: 2 | H8: =SUM(D8:F8) -> 12
B9: IA6 | C9: Observations raised | D9: 38 | E9: 45 | F9: 52 | G9: 40 | H9: =SUM(D9:F9) -> 135
B10: IA7 | C10: Observations complied | D10: 35 | E10: 40 | F10: 44 | G10: 30 | H10: =SUM(D10:F10) -> 119
B11: IA9 | C11: Closure % | D11: =D10/D9 -> 0.92105263 | E11: =E10/E9 -> 0.88888889 | F11: =F10/F9 -> 0.84615385 | G11: =G10/G9 -> 0.75 | H11: =H10/H9 -> 0.88148148
B12: C | C12: Areas covered (of 12) | D12: 12 | E12: 11 | F12: 10 | G12: 8
B13: C% | C13: Area coverage % | D13: =D12/12 -> 1 | E13: =E12/12 -> 0.91666667 | F13: =F12/12 -> 0.83333333 | G13: =G12/12 -> 0.66666667
B15: Step 2 – Statutory audit
B16: Code | C16: Particulars | D16: FY 2025-26 | E16: FY 2024-25 | F16: FY 2023-24 | G16: FY 2022-23 | H16: NAAC 3-Yr
B17: SA4 | C17: Audit report date | D17: 46262 | E17: 45910 | F17: 45560 | G17: 45214
B18: SA5 | C18: Days from FY end to report | D18: =D17-DATE(2026,3,31) -> 150 | E18: =E17-DATE(2025,3,31) -> 163 | F18: =F17-DATE(2024,3,31) -> 178 | G18: =G17-DATE(2023,3,31) -> 198
B19: SA6 | C19: Audit opinion | D19: Unqualified | E19: Unqualified | F19: Unqualified | G19: Unqualified
B20: SA7 | C20: Observations raised | D20: 6 | E20: 8 | F20: 10 | G20: 12 | H20: =SUM(D20:F20) -> 24
B21: SA8 | C21: Observations complied | D21: 6 | E21: 7 | F21: 8 | G21: 8 | H21: =SUM(D21:F21) -> 21
B22: SA10 | C22: Closure % | D22: =D21/D20 -> 1 | E22: =E21/E20 -> 0.875 | F22: =F21/F20 -> 0.8 | G22: =G21/G20 -> 0.66666667 | H22: =H21/H20 -> 0.875
B24: Step 3 – Risk management
B25: Code | C25: Particulars | D25: FY 2025-26 | E25: FY 2024-25 | F25: FY 2023-24 | G25: FY 2022-23 | H25: NAAC 3-Yr
B26: D1 | C26: Approaches implemented (of 12) | D26: 11 | E26: 9 | F26: 7 | G26: 4
B27: D4 | C27: Interpretation | D27: =IF(D26>=9,"Comprehensive",IF(D26>=6,"Established",IF(D26>=1,"Developing","Not in place"))) -> Comprehensive | E27: =IF(E26>=9,"Comprehensive",IF(E26>=6,"Established",IF(E26>=1,"Developing","Not in place"))) -> Comprehensive | F27: =IF(F26>=9,"Comprehensive",IF(F26>=6,"Established",IF(F26>=1,"Developing","Not in place"))) -> Established | G27: =IF(G26>=9,"Comprehensive",IF(G26>=6,"Established",IF(G26>=1,"Developing","Not in place"))) -> Developing
B29: How to read this example
B30: 1. Option (a) – YES: Internal audit was done quarterly in all three NAAC years (12 reports). Observation closure improved from 75.0% (FY 2022-23) to 84.6%, 88.9% and 92.1% (FY 2025-26 – Strong), and coverage widened to all 12 audit areas. 2. Option (b) – YES: Statutory audit reports were issued every year with an unqualified opinion. The time taken to close the audit fell from 198 days to 150 days after year-end (Timely). Statutory observations closed fully (100%) in FY 2025-26. 3. Option (c) – YES: Risk management approaches grew from 4 (Developing) to 11 of 12 (Comprehensive) after a board-approved policy and risk register were introduced. 4. In the narrative, show improvement over time: more frequent audits, better closure, faster audit and a maturing risk framework demonstrate effective financial control.

Sheet 9. Document Checklist
B2: SHEET 9 – SUPPORTING DOCUMENT CHECKLIST
B3: Select the status for each document and financial year (Available / Pending / Not Applicable). Items 1 and 2 are mandatory as per NAAC; the rest are recommended evidence for Data Validation & Verification (DVV).
B5: # | C5: Document | D5: Purpose / What to highlight | E5: FY 2025-26 | F5: FY 2024-25 | G5: FY 2023-24 | H5: FY 2022-23 | I5: Responsibility | J5: File name / Link / Remarks
B6: 1 | C6: Audited Income & Expenditure statement & Balance Sheet – certified by CA (MANDATORY) | D6: Auditor's report, signature, UDIN, countersignature | E6: Pending | F6: Pending | G6: Pending | H6: Pending | I6: Finance Officer
B7: 2 | C7: CA-certified audit extract (MANDATORY – Sheet 10 format) | D7: Must match Sheet 7 | E7: Pending | F7: Pending | G7: Pending | H7: Pending | I7: CA / Finance Officer
B8: 3 | C8: Internal auditor appointment letter & scope of work | D8: Option (a) | E8: Pending | F8: Pending | G8: Pending | H8: Pending | I8: Finance Officer
B9: 4 | C9: Internal audit reports | D9: Option (a) – one per audit cycle | E9: Pending | F9: Pending | G9: Pending | H9: Pending | I9: Internal Auditor
B10: 5 | C10: Action Taken Reports (ATR) on internal audit | D10: Closure of observations | E10: Pending | F10: Pending | G10: Pending | H10: Pending | I10: Finance Office
B11: 6 | C11: Statutory auditor appointment resolution | D11: Option (b) | E11: Pending | F11: Pending | G11: Pending | H11: Pending | I11: Registrar
B12: 7 | C12: Statutory audit report with management replies | D12: Opinion and observations | E12: Pending | F12: Pending | G12: Pending | H12: Pending | I12: Finance Office
B13: 8 | C13: Finance Committee & BOM minutes approving audited accounts | D13: Option (b) | E13: Pending | F13: Pending | G13: Pending | H13: Pending | I13: Registrar
B14: 9 | C14: Income-tax audit report (Form 10B / 10BB) & GST reconciliation | D14: Other external audits | E14: Pending | F14: Pending | G14: Pending | H14: Pending | I14: Accounts Head
B15: 10 | C15: Risk Management Policy (approved) | D15: Option (c) | E15: Pending | F15: Pending | G15: Pending | H15: Pending | I15: Finance Officer
B16: 11 | C16: Risk register & Risk / Audit Committee minutes | D16: Option (c) | E16: Pending | F16: Pending | G16: Pending | H16: Pending | I16: Finance Officer / IQAC
B17: 12 | C17: Delegation of financial powers ordinance / SOP | D17: Option (c) – links to Metric 7.2 | E17: Pending | F17: Pending | G17: Pending | H17: Pending | I17: Registrar
B18: 13 | C18: Insurance policies (assets, students, staff) | D18: Option (c) | E18: Pending | F18: Pending | G18: Pending | H18: Pending | I18: Estate / Finance Office
C19: Documents Available (count) | E19: =COUNTIF(E6:E18,"Available")&" / "&(13-COUNTIF(E6:E18,"Not Applicable")) -> 0 / 13 | F19: =COUNTIF(F6:F18,"Available")&" / "&(13-COUNTIF(F6:F18,"Not Applicable")) -> 0 / 13 | G19: =COUNTIF(G6:G18,"Available")&" / "&(13-COUNTIF(G6:G18,"Not Applicable")) -> 0 / 13 | H19: =COUNTIF(H6:H18,"Available")&" / "&(13-COUNTIF(H6:H18,"Not Applicable")) -> 0 / 13

Sheet 10. CA Certificate
B2: CERTIFICATE BY CHARTERED ACCOUNTANT
B3: (To be printed on the letterhead of the Chartered Accountant firm)
B5: Ref. No.: ____________________ Date: ____________________
B6: Sub.: Certificate on Financial Controls of [University Name] for NAAC Metric 4.4 – Financial Controls and Risk Management (Binary Accreditation Framework) – Financial Years 2022-23 to 2025-26
B8: This is to certify that, based on our examination of the audited financial statements, audit reports, internal audit reports and related records of [University Name], the following mechanisms of financial control were in place during the financial years mentioned below:
B10: S. No. | C10: Financial Year | D10: Internal audit reports issued | E10: Statutory audit report date | F10: Audit opinion | G10: Days from year-end
B11: 1 | C11: FY 2025-26 | D11: ='7. Summary & Compliance'!D16 -> 0 | E11: ='7. Summary & Compliance'!D26 -> - | F11: ='7. Summary & Compliance'!D28 -> - | G11: ='7. Summary & Compliance'!D27 -> -
B12: 2 | C12: FY 2024-25 | D12: ='7. Summary & Compliance'!E16 -> 0 | E12: ='7. Summary & Compliance'!E26 -> - | F12: ='7. Summary & Compliance'!E28 -> - | G12: ='7. Summary & Compliance'!E27 -> -
B13: 3 | C13: FY 2023-24 | D13: ='7. Summary & Compliance'!F16 -> 0 | E13: ='7. Summary & Compliance'!F26 -> - | F13: ='7. Summary & Compliance'!F28 -> - | G13: ='7. Summary & Compliance'!F27 -> -
B14: 4 | C14: FY 2022-23 | D14: ='7. Summary & Compliance'!G16 -> 0 | E14: ='7. Summary & Compliance'!G26 -> - | F14: ='7. Summary & Compliance'!G28 -> - | G14: ='7. Summary & Compliance'!G27 -> -
B16: We further certify that (i) the accounts of the University for each of the above years have been audited by an independent Chartered Accountant firm and approved by the competent authorities; (ii) internal audits were carried out during the years as indicated above; (iii) other external audits such as income-tax audit were conducted where applicable; and (iv) the University has the risk management mechanisms recorded in its risk management policy and risk register. The relevant components have been highlighted in the audited statements enclosed herewith.
B19: For ____________________ (CA Firm Name) | E19: Countersigned by
B20: Chartered Accountants, FRN: __________ | E20: Registrar / Finance Officer
E21: [University Name]
B22: (Signature & Seal) | E22: (Signature & Seal)
B23: Name of Partner: ____________________
B24: Membership No.: __________ UDIN: __________
B26: Place: [City] Enclosures: Audited statements, audit reports and internal audit summaries for FY 2022-23 to 2025-26
